Main_server.py 131 SocketLoop DEBUG => using socket to input

Main_server.py 185 Handler DEBUG => exception:
Traceback (most recent call last):
  File "C:\Users\qwe\AppData\Local\Programs\Python\Python37-32\lib\threading.py", line 885, in _bootstrap
    self._bootstrap_inner()
    ©¦    ©¸ <function Thread._bootstrap_inner at 0x03128108>
    ©¸ <Thread(Thread-2, started daemon 31648)>
  File "C:\Users\qwe\AppData\Local\Programs\Python\Python37-32\lib\threading.py", line 917, in _bootstrap_inner
    self.run()
    ©¦    ©¸ <function Thread.run at 0x03124FA8>
    ©¸ <Thread(Thread-2, started daemon 31648)>
  File "C:\Users\qwe\AppData\Local\Programs\Python\Python37-32\lib\threading.py", line 865, in run
    self._target(*self._args, **self._kwargs)
    ©¦    ©¦        ©¦    ©¦        ©¦    ©¸ {}
    ©¦    ©¦        ©¦    ©¦        ©¸ <Thread(Thread-2, started daemon 31648)>
    ©¦    ©¦        ©¦    ©¸ ()
    ©¦    ©¦        ©¸ <Thread(Thread-2, started daemon 31648)>
    ©¦    ©¸ <bound method GetTodo.Handler of <__main__.GetTodo object at 0x02FAA5D0>>
    ©¸ <Thread(Thread-2, started daemon 31648)>

> File "D:\\gvim\\vimfiles\\myplug\\ECY_new\\python/server/Main_server.py", line 180, in Handler
    todo_dict = self.event_handler.Pass2Hanlder(todo_dict)
    ©¦           ©¦    ©¦             ©¦            ©¸ {'Msg': {'AllTextList': '\n', 'CurrentLineText': '', 'FileType': 'leaderf', 'FilePath': 'D:\\gvim\\vim81\\Mru\\LeaderF', 'Sta...
    ©¦           ©¦    ©¦             ©¸ <function EventHandler.Pass2Hanlder at 0x0324A4B0>
    ©¦           ©¦    ©¸ <__main__.EventHandler object at 0x0329B730>
    ©¦           ©¸ <__main__.GetTodo object at 0x02FAA5D0>
    ©¸ {'Msg': {'AllTextList': '\n', 'CurrentLineText': '', 'FileType': 'leaderf', 'FilePath': 'D:\\gvim\\vim81\\Mru\\LeaderF', 'Sta...

  File "D:\\gvim\\vimfiles\\myplug\\ECY_new\\python/server/Main_server.py", line 241, in Pass2Hanlder
    raise

RuntimeError: No active exception to reraise

Traceback (most recent call last):
  File "C:\Users\qwe\AppData\Local\Programs\Python\Python37-32\lib\threading.py", line 885, in _bootstrap
    self._bootstrap_inner()
    ©¦    ©¸ <function Thread._bootstrap_inner at 0x03128108>
    ©¸ <Thread(Thread-2, started daemon 31648)>
  File "C:\Users\qwe\AppData\Local\Programs\Python\Python37-32\lib\threading.py", line 917, in _bootstrap_inner
    self.run()
    ©¦    ©¸ <function Thread.run at 0x03124FA8>
    ©¸ <Thread(Thread-2, started daemon 31648)>
  File "C:\Users\qwe\AppData\Local\Programs\Python\Python37-32\lib\threading.py", line 865, in run
    self._target(*self._args, **self._kwargs)
    ©¦    ©¦        ©¦    ©¦        ©¦    ©¸ {}
    ©¦    ©¦        ©¦    ©¦        ©¸ <Thread(Thread-2, started daemon 31648)>
    ©¦    ©¦        ©¦    ©¸ ()
    ©¦    ©¦        ©¸ <Thread(Thread-2, started daemon 31648)>
    ©¦    ©¸ <bound method GetTodo.Handler of <__main__.GetTodo object at 0x02FAA5D0>>
    ©¸ <Thread(Thread-2, started daemon 31648)>

> File "D:\\gvim\\vimfiles\\myplug\\ECY_new\\python/server/Main_server.py", line 180, in Handler
    todo_dict = self.event_handler.Pass2Hanlder(todo_dict)
    ©¦           ©¦    ©¦             ©¦            ©¸ {'Msg': {'AllTextList': '\n', 'CurrentLineText': '', 'FileType': 'leaderf', 'FilePath': 'D:\\gvim\\vim81\\Mru\\LeaderF', 'Sta...
    ©¦           ©¦    ©¦             ©¸ <function EventHandler.Pass2Hanlder at 0x0324A4B0>
    ©¦           ©¦    ©¸ <__main__.EventHandler object at 0x0329B730>
    ©¦           ©¸ <__main__.GetTodo object at 0x02FAA5D0>
    ©¸ {'Msg': {'AllTextList': '\n', 'CurrentLineText': '', 'FileType': 'leaderf', 'FilePath': 'D:\\gvim\\vim81\\Mru\\LeaderF', 'Sta...

  File "D:\\gvim\\vimfiles\\myplug\\ECY_new\\python/server/Main_server.py", line 241, in Pass2Hanlder
    raise

RuntimeError: No active exception to reraise
Main_server.py 185 Handler DEBUG => exception:
Traceback (most recent call last):
  File "C:\Users\qwe\AppData\Local\Programs\Python\Python37-32\lib\threading.py", line 885, in _bootstrap
    self._bootstrap_inner()
    ©¦    ©¸ <function Thread._bootstrap_inner at 0x03128108>
    ©¸ <Thread(Thread-2, started daemon 31648)>
  File "C:\Users\qwe\AppData\Local\Programs\Python\Python37-32\lib\threading.py", line 917, in _bootstrap_inner
    self.run()
    ©¦    ©¸ <function Thread.run at 0x03124FA8>
    ©¸ <Thread(Thread-2, started daemon 31648)>
  File "C:\Users\qwe\AppData\Local\Programs\Python\Python37-32\lib\threading.py", line 865, in run
    self._target(*self._args, **self._kwargs)
    ©¦    ©¦        ©¦    ©¦        ©¦    ©¸ {}
    ©¦    ©¦        ©¦    ©¦        ©¸ <Thread(Thread-2, started daemon 31648)>
    ©¦    ©¦        ©¦    ©¸ ()
    ©¦    ©¦        ©¸ <Thread(Thread-2, started daemon 31648)>
    ©¦    ©¸ <bound method GetTodo.Handler of <__main__.GetTodo object at 0x02FAA5D0>>
    ©¸ <Thread(Thread-2, started daemon 31648)>

> File "D:\\gvim\\vimfiles\\myplug\\ECY_new\\python/server/Main_server.py", line 180, in Handler
    todo_dict = self.event_handler.Pass2Hanlder(todo_dict)
    ©¦           ©¦    ©¦             ©¦            ©¸ {'Msg': {'AllTextList': 'if has(\'win32\')\n  set guifont=DejaVu\\ Sans\\ Mono\\ for\\ Powerline\\:h12\n  source $vimruntime/...
    ©¦           ©¦    ©¦             ©¸ <function EventHandler.Pass2Hanlder at 0x0324A4B0>
    ©¦           ©¦    ©¸ <__main__.EventHandler object at 0x0329B730>
    ©¦           ©¸ <__main__.GetTodo object at 0x02FAA5D0>
    ©¸ {'Msg': {'AllTextList': 'if has(\'win32\')\n  set guifont=DejaVu\\ Sans\\ Mono\\ for\\ Powerline\\:h12\n  source $vimruntime/...

  File "D:\\gvim\\vimfiles\\myplug\\ECY_new\\python/server/Main_server.py", line 241, in Pass2Hanlder
    raise

RuntimeError: No active exception to reraise

Traceback (most recent call last):
  File "C:\Users\qwe\AppData\Local\Programs\Python\Python37-32\lib\threading.py", line 885, in _bootstrap
    self._bootstrap_inner()
    ©¦    ©¸ <function Thread._bootstrap_inner at 0x03128108>
    ©¸ <Thread(Thread-2, started daemon 31648)>
  File "C:\Users\qwe\AppData\Local\Programs\Python\Python37-32\lib\threading.py", line 917, in _bootstrap_inner
    self.run()
    ©¦    ©¸ <function Thread.run at 0x03124FA8>
    ©¸ <Thread(Thread-2, started daemon 31648)>
  File "C:\Users\qwe\AppData\Local\Programs\Python\Python37-32\lib\threading.py", line 865, in run
    self._target(*self._args, **self._kwargs)
    ©¦    ©¦        ©¦    ©¦        ©¦    ©¸ {}
    ©¦    ©¦        ©¦    ©¦        ©¸ <Thread(Thread-2, started daemon 31648)>
    ©¦    ©¦        ©¦    ©¸ ()
    ©¦    ©¦        ©¸ <Thread(Thread-2, started daemon 31648)>
    ©¦    ©¸ <bound method GetTodo.Handler of <__main__.GetTodo object at 0x02FAA5D0>>
    ©¸ <Thread(Thread-2, started daemon 31648)>

> File "D:\\gvim\\vimfiles\\myplug\\ECY_new\\python/server/Main_server.py", line 180, in Handler
    todo_dict = self.event_handler.Pass2Hanlder(todo_dict)
    ©¦           ©¦    ©¦             ©¦            ©¸ {'Msg': {'AllTextList': 'if has(\'win32\')\n  set guifont=DejaVu\\ Sans\\ Mono\\ for\\ Powerline\\:h12\n  source $vimruntime/...
    ©¦           ©¦    ©¦             ©¸ <function EventHandler.Pass2Hanlder at 0x0324A4B0>
    ©¦           ©¦    ©¸ <__main__.EventHandler object at 0x0329B730>
    ©¦           ©¸ <__main__.GetTodo object at 0x02FAA5D0>
    ©¸ {'Msg': {'AllTextList': 'if has(\'win32\')\n  set guifont=DejaVu\\ Sans\\ Mono\\ for\\ Powerline\\:h12\n  source $vimruntime/...

  File "D:\\gvim\\vimfiles\\myplug\\ECY_new\\python/server/Main_server.py", line 241, in Pass2Hanlder
    raise

RuntimeError: No active exception to reraise
Main_server.py 185 Handler DEBUG => exception:
Traceback (most recent call last):
  File "C:\Users\qwe\AppData\Local\Programs\Python\Python37-32\lib\threading.py", line 885, in _bootstrap
    self._bootstrap_inner()
    ©¦    ©¸ <function Thread._bootstrap_inner at 0x03128108>
    ©¸ <Thread(Thread-2, started daemon 31648)>
  File "C:\Users\qwe\AppData\Local\Programs\Python\Python37-32\lib\threading.py", line 917, in _bootstrap_inner
    self.run()
    ©¦    ©¸ <function Thread.run at 0x03124FA8>
    ©¸ <Thread(Thread-2, started daemon 31648)>
  File "C:\Users\qwe\AppData\Local\Programs\Python\Python37-32\lib\threading.py", line 865, in run
    self._target(*self._args, **self._kwargs)
    ©¦    ©¦        ©¦    ©¦        ©¦    ©¸ {}
    ©¦    ©¦        ©¦    ©¦        ©¸ <Thread(Thread-2, started daemon 31648)>
    ©¦    ©¦        ©¦    ©¸ ()
    ©¦    ©¦        ©¸ <Thread(Thread-2, started daemon 31648)>
    ©¦    ©¸ <bound method GetTodo.Handler of <__main__.GetTodo object at 0x02FAA5D0>>
    ©¸ <Thread(Thread-2, started daemon 31648)>

> File "D:\\gvim\\vimfiles\\myplug\\ECY_new\\python/server/Main_server.py", line 180, in Handler
    todo_dict = self.event_handler.Pass2Hanlder(todo_dict)
    ©¦           ©¦    ©¦             ©¦            ©¸ {'Msg': {'AllTextList': '\n" must put these outside a function\nlet  s:python_script_folder_path = expand( \'<sfile>:p:h:h\' ...
    ©¦           ©¦    ©¦             ©¸ <function EventHandler.Pass2Hanlder at 0x0324A4B0>
    ©¦           ©¦    ©¸ <__main__.EventHandler object at 0x0329B730>
    ©¦           ©¸ <__main__.GetTodo object at 0x02FAA5D0>
    ©¸ {'Msg': {'AllTextList': '\n" must put these outside a function\nlet  s:python_script_folder_path = expand( \'<sfile>:p:h:h\' ...

  File "D:\\gvim\\vimfiles\\myplug\\ECY_new\\python/server/Main_server.py", line 241, in Pass2Hanlder
    raise

RuntimeError: No active exception to reraise

Traceback (most recent call last):
  File "C:\Users\qwe\AppData\Local\Programs\Python\Python37-32\lib\threading.py", line 885, in _bootstrap
    self._bootstrap_inner()
    ©¦    ©¸ <function Thread._bootstrap_inner at 0x03128108>
    ©¸ <Thread(Thread-2, started daemon 31648)>
  File "C:\Users\qwe\AppData\Local\Programs\Python\Python37-32\lib\threading.py", line 917, in _bootstrap_inner
    self.run()
    ©¦    ©¸ <function Thread.run at 0x03124FA8>
    ©¸ <Thread(Thread-2, started daemon 31648)>
  File "C:\Users\qwe\AppData\Local\Programs\Python\Python37-32\lib\threading.py", line 865, in run
    self._target(*self._args, **self._kwargs)
    ©¦    ©¦        ©¦    ©¦        ©¦    ©¸ {}
    ©¦    ©¦        ©¦    ©¦        ©¸ <Thread(Thread-2, started daemon 31648)>
    ©¦    ©¦        ©¦    ©¸ ()
    ©¦    ©¦        ©¸ <Thread(Thread-2, started daemon 31648)>
    ©¦    ©¸ <bound method GetTodo.Handler of <__main__.GetTodo object at 0x02FAA5D0>>
    ©¸ <Thread(Thread-2, started daemon 31648)>

> File "D:\\gvim\\vimfiles\\myplug\\ECY_new\\python/server/Main_server.py", line 180, in Handler
    todo_dict = self.event_handler.Pass2Hanlder(todo_dict)
    ©¦           ©¦    ©¦             ©¦            ©¸ {'Msg': {'AllTextList': '\n" must put these outside a function\nlet  s:python_script_folder_path = expand( \'<sfile>:p:h:h\' ...
    ©¦           ©¦    ©¦             ©¸ <function EventHandler.Pass2Hanlder at 0x0324A4B0>
    ©¦           ©¦    ©¸ <__main__.EventHandler object at 0x0329B730>
    ©¦           ©¸ <__main__.GetTodo object at 0x02FAA5D0>
    ©¸ {'Msg': {'AllTextList': '\n" must put these outside a function\nlet  s:python_script_folder_path = expand( \'<sfile>:p:h:h\' ...

  File "D:\\gvim\\vimfiles\\myplug\\ECY_new\\python/server/Main_server.py", line 241, in Pass2Hanlder
    raise

RuntimeError: No active exception to reraise
Main_server.py 185 Handler DEBUG => exception:
Traceback (most recent call last):
  File "C:\Users\qwe\AppData\Local\Programs\Python\Python37-32\lib\threading.py", line 885, in _bootstrap
    self._bootstrap_inner()
    ©¦    ©¸ <function Thread._bootstrap_inner at 0x03128108>
    ©¸ <Thread(Thread-2, started daemon 31648)>
  File "C:\Users\qwe\AppData\Local\Programs\Python\Python37-32\lib\threading.py", line 917, in _bootstrap_inner
    self.run()
    ©¦    ©¸ <function Thread.run at 0x03124FA8>
    ©¸ <Thread(Thread-2, started daemon 31648)>
  File "C:\Users\qwe\AppData\Local\Programs\Python\Python37-32\lib\threading.py", line 865, in run
    self._target(*self._args, **self._kwargs)
    ©¦    ©¦        ©¦    ©¦        ©¦    ©¸ {}
    ©¦    ©¦        ©¦    ©¦        ©¸ <Thread(Thread-2, started daemon 31648)>
    ©¦    ©¦        ©¦    ©¸ ()
    ©¦    ©¦        ©¸ <Thread(Thread-2, started daemon 31648)>
    ©¦    ©¸ <bound method GetTodo.Handler of <__main__.GetTodo object at 0x02FAA5D0>>
    ©¸ <Thread(Thread-2, started daemon 31648)>

> File "D:\\gvim\\vimfiles\\myplug\\ECY_new\\python/server/Main_server.py", line 180, in Handler
    todo_dict = self.event_handler.Pass2Hanlder(todo_dict)
    ©¦           ©¦    ©¦             ©¦            ©¸ {'Msg': {'AllTextList': '\n" must put these outside a function\nlet  s:python_script_folder_path = expand( \'<sfile>:p:h:h\' ...
    ©¦           ©¦    ©¦             ©¸ <function EventHandler.Pass2Hanlder at 0x0324A4B0>
    ©¦           ©¦    ©¸ <__main__.EventHandler object at 0x0329B730>
    ©¦           ©¸ <__main__.GetTodo object at 0x02FAA5D0>
    ©¸ {'Msg': {'AllTextList': '\n" must put these outside a function\nlet  s:python_script_folder_path = expand( \'<sfile>:p:h:h\' ...

  File "D:\\gvim\\vimfiles\\myplug\\ECY_new\\python/server/Main_server.py", line 241, in Pass2Hanlder
    raise

RuntimeError: No active exception to reraise

Traceback (most recent call last):
  File "C:\Users\qwe\AppData\Local\Programs\Python\Python37-32\lib\threading.py", line 885, in _bootstrap
    self._bootstrap_inner()
    ©¦    ©¸ <function Thread._bootstrap_inner at 0x03128108>
    ©¸ <Thread(Thread-2, started daemon 31648)>
  File "C:\Users\qwe\AppData\Local\Programs\Python\Python37-32\lib\threading.py", line 917, in _bootstrap_inner
    self.run()
    ©¦    ©¸ <function Thread.run at 0x03124FA8>
    ©¸ <Thread(Thread-2, started daemon 31648)>
  File "C:\Users\qwe\AppData\Local\Programs\Python\Python37-32\lib\threading.py", line 865, in run
    self._target(*self._args, **self._kwargs)
    ©¦    ©¦        ©¦    ©¦        ©¦    ©¸ {}
    ©¦    ©¦        ©¦    ©¦        ©¸ <Thread(Thread-2, started daemon 31648)>
    ©¦    ©¦        ©¦    ©¸ ()
    ©¦    ©¦        ©¸ <Thread(Thread-2, started daemon 31648)>
    ©¦    ©¸ <bound method GetTodo.Handler of <__main__.GetTodo object at 0x02FAA5D0>>
    ©¸ <Thread(Thread-2, started daemon 31648)>

> File "D:\\gvim\\vimfiles\\myplug\\ECY_new\\python/server/Main_server.py", line 180, in Handler
    todo_dict = self.event_handler.Pass2Hanlder(todo_dict)
    ©¦           ©¦    ©¦             ©¦            ©¸ {'Msg': {'AllTextList': '\n" must put these outside a function\nlet  s:python_script_folder_path = expand( \'<sfile>:p:h:h\' ...
    ©¦           ©¦    ©¦             ©¸ <function EventHandler.Pass2Hanlder at 0x0324A4B0>
    ©¦           ©¦    ©¸ <__main__.EventHandler object at 0x0329B730>
    ©¦           ©¸ <__main__.GetTodo object at 0x02FAA5D0>
    ©¸ {'Msg': {'AllTextList': '\n" must put these outside a function\nlet  s:python_script_folder_path = expand( \'<sfile>:p:h:h\' ...

  File "D:\\gvim\\vimfiles\\myplug\\ECY_new\\python/server/Main_server.py", line 241, in Pass2Hanlder
    raise

RuntimeError: No active exception to reraise
Main_server.py 185 Handler DEBUG => exception:
Traceback (most recent call last):
  File "C:\Users\qwe\AppData\Local\Programs\Python\Python37-32\lib\threading.py", line 885, in _bootstrap
    self._bootstrap_inner()
    ©¦    ©¸ <function Thread._bootstrap_inner at 0x03128108>
    ©¸ <Thread(Thread-2, started daemon 31648)>
  File "C:\Users\qwe\AppData\Local\Programs\Python\Python37-32\lib\threading.py", line 917, in _bootstrap_inner
    self.run()
    ©¦    ©¸ <function Thread.run at 0x03124FA8>
    ©¸ <Thread(Thread-2, started daemon 31648)>
  File "C:\Users\qwe\AppData\Local\Programs\Python\Python37-32\lib\threading.py", line 865, in run
    self._target(*self._args, **self._kwargs)
    ©¦    ©¦        ©¦    ©¦        ©¦    ©¸ {}
    ©¦    ©¦        ©¦    ©¦        ©¸ <Thread(Thread-2, started daemon 31648)>
    ©¦    ©¦        ©¦    ©¸ ()
    ©¦    ©¦        ©¸ <Thread(Thread-2, started daemon 31648)>
    ©¦    ©¸ <bound method GetTodo.Handler of <__main__.GetTodo object at 0x02FAA5D0>>
    ©¸ <Thread(Thread-2, started daemon 31648)>

> File "D:\\gvim\\vimfiles\\myplug\\ECY_new\\python/server/Main_server.py", line 180, in Handler
    todo_dict = self.event_handler.Pass2Hanlder(todo_dict)
    ©¦           ©¦    ©¦             ©¦            ©¸ {'Msg': {'AllTextList': '\n', 'CurrentLineText': '', 'FileType': '', 'FilePath': 'D:\\gvim\\5', 'StartPosition': {'Line': 0, ...
    ©¦           ©¦    ©¦             ©¸ <function EventHandler.Pass2Hanlder at 0x0324A4B0>
    ©¦           ©¦    ©¸ <__main__.EventHandler object at 0x0329B730>
    ©¦           ©¸ <__main__.GetTodo object at 0x02FAA5D0>
    ©¸ {'Msg': {'AllTextList': '\n', 'CurrentLineText': '', 'FileType': '', 'FilePath': 'D:\\gvim\\5', 'StartPosition': {'Line': 0, ...

  File "D:\\gvim\\vimfiles\\myplug\\ECY_new\\python/server/Main_server.py", line 241, in Pass2Hanlder
    raise

RuntimeError: No active exception to reraise

Traceback (most recent call last):
  File "C:\Users\qwe\AppData\Local\Programs\Python\Python37-32\lib\threading.py", line 885, in _bootstrap
    self._bootstrap_inner()
    ©¦    ©¸ <function Thread._bootstrap_inner at 0x03128108>
    ©¸ <Thread(Thread-2, started daemon 31648)>
  File "C:\Users\qwe\AppData\Local\Programs\Python\Python37-32\lib\threading.py", line 917, in _bootstrap_inner
    self.run()
    ©¦    ©¸ <function Thread.run at 0x03124FA8>
    ©¸ <Thread(Thread-2, started daemon 31648)>
  File "C:\Users\qwe\AppData\Local\Programs\Python\Python37-32\lib\threading.py", line 865, in run
    self._target(*self._args, **self._kwargs)
    ©¦    ©¦        ©¦    ©¦        ©¦    ©¸ {}
    ©¦    ©¦        ©¦    ©¦        ©¸ <Thread(Thread-2, started daemon 31648)>
    ©¦    ©¦        ©¦    ©¸ ()
    ©¦    ©¦        ©¸ <Thread(Thread-2, started daemon 31648)>
    ©¦    ©¸ <bound method GetTodo.Handler of <__main__.GetTodo object at 0x02FAA5D0>>
    ©¸ <Thread(Thread-2, started daemon 31648)>

> File "D:\\gvim\\vimfiles\\myplug\\ECY_new\\python/server/Main_server.py", line 180, in Handler
    todo_dict = self.event_handler.Pass2Hanlder(todo_dict)
    ©¦           ©¦    ©¦             ©¦            ©¸ {'Msg': {'AllTextList': '\n', 'CurrentLineText': '', 'FileType': '', 'FilePath': 'D:\\gvim\\5', 'StartPosition': {'Line': 0, ...
    ©¦           ©¦    ©¦             ©¸ <function EventHandler.Pass2Hanlder at 0x0324A4B0>
    ©¦           ©¦    ©¸ <__main__.EventHandler object at 0x0329B730>
    ©¦           ©¸ <__main__.GetTodo object at 0x02FAA5D0>
    ©¸ {'Msg': {'AllTextList': '\n', 'CurrentLineText': '', 'FileType': '', 'FilePath': 'D:\\gvim\\5', 'StartPosition': {'Line': 0, ...

  File "D:\\gvim\\vimfiles\\myplug\\ECY_new\\python/server/Main_server.py", line 241, in Pass2Hanlder
    raise

RuntimeError: No active exception to reraise
Main_server.py 185 Handler DEBUG => exception:
Traceback (most recent call last):
  File "C:\Users\qwe\AppData\Local\Programs\Python\Python37-32\lib\threading.py", line 885, in _bootstrap
    self._bootstrap_inner()
    ©¦    ©¸ <function Thread._bootstrap_inner at 0x03128108>
    ©¸ <Thread(Thread-2, started daemon 31648)>
  File "C:\Users\qwe\AppData\Local\Programs\Python\Python37-32\lib\threading.py", line 917, in _bootstrap_inner
    self.run()
    ©¦    ©¸ <function Thread.run at 0x03124FA8>
    ©¸ <Thread(Thread-2, started daemon 31648)>
  File "C:\Users\qwe\AppData\Local\Programs\Python\Python37-32\lib\threading.py", line 865, in run
    self._target(*self._args, **self._kwargs)
    ©¦    ©¦        ©¦    ©¦        ©¦    ©¸ {}
    ©¦    ©¦        ©¦    ©¦        ©¸ <Thread(Thread-2, started daemon 31648)>
    ©¦    ©¦        ©¦    ©¸ ()
    ©¦    ©¦        ©¸ <Thread(Thread-2, started daemon 31648)>
    ©¦    ©¸ <bound method GetTodo.Handler of <__main__.GetTodo object at 0x02FAA5D0>>
    ©¸ <Thread(Thread-2, started daemon 31648)>

> File "D:\\gvim\\vimfiles\\myplug\\ECY_new\\python/server/Main_server.py", line 180, in Handler
    todo_dict = self.event_handler.Pass2Hanlder(todo_dict)
    ©¦           ©¦    ©¦             ©¦            ©¸ {'Msg': {'AllTextList': '\n', 'CurrentLineText': '', 'FileType': '', 'FilePath': 'D:\\gvim\\NERD_tree_1', 'StartPosition': {'...
    ©¦           ©¦    ©¦             ©¸ <function EventHandler.Pass2Hanlder at 0x0324A4B0>
    ©¦           ©¦    ©¸ <__main__.EventHandler object at 0x0329B730>
    ©¦           ©¸ <__main__.GetTodo object at 0x02FAA5D0>
    ©¸ {'Msg': {'AllTextList': '\n', 'CurrentLineText': '', 'FileType': '', 'FilePath': 'D:\\gvim\\NERD_tree_1', 'StartPosition': {'...

  File "D:\\gvim\\vimfiles\\myplug\\ECY_new\\python/server/Main_server.py", line 241, in Pass2Hanlder
    raise

RuntimeError: No active exception to reraise

Traceback (most recent call last):
  File "C:\Users\qwe\AppData\Local\Programs\Python\Python37-32\lib\threading.py", line 885, in _bootstrap
    self._bootstrap_inner()
    ©¦    ©¸ <function Thread._bootstrap_inner at 0x03128108>
    ©¸ <Thread(Thread-2, started daemon 31648)>
  File "C:\Users\qwe\AppData\Local\Programs\Python\Python37-32\lib\threading.py", line 917, in _bootstrap_inner
    self.run()
    ©¦    ©¸ <function Thread.run at 0x03124FA8>
    ©¸ <Thread(Thread-2, started daemon 31648)>
  File "C:\Users\qwe\AppData\Local\Programs\Python\Python37-32\lib\threading.py", line 865, in run
    self._target(*self._args, **self._kwargs)
    ©¦    ©¦        ©¦    ©¦        ©¦    ©¸ {}
    ©¦    ©¦        ©¦    ©¦        ©¸ <Thread(Thread-2, started daemon 31648)>
    ©¦    ©¦        ©¦    ©¸ ()
    ©¦    ©¦        ©¸ <Thread(Thread-2, started daemon 31648)>
    ©¦    ©¸ <bound method GetTodo.Handler of <__main__.GetTodo object at 0x02FAA5D0>>
    ©¸ <Thread(Thread-2, started daemon 31648)>

> File "D:\\gvim\\vimfiles\\myplug\\ECY_new\\python/server/Main_server.py", line 180, in Handler
    todo_dict = self.event_handler.Pass2Hanlder(todo_dict)
    ©¦           ©¦    ©¦             ©¦            ©¸ {'Msg': {'AllTextList': '\n', 'CurrentLineText': '', 'FileType': '', 'FilePath': 'D:\\gvim\\NERD_tree_1', 'StartPosition': {'...
    ©¦           ©¦    ©¦             ©¸ <function EventHandler.Pass2Hanlder at 0x0324A4B0>
    ©¦           ©¦    ©¸ <__main__.EventHandler object at 0x0329B730>
    ©¦           ©¸ <__main__.GetTodo object at 0x02FAA5D0>
    ©¸ {'Msg': {'AllTextList': '\n', 'CurrentLineText': '', 'FileType': '', 'FilePath': 'D:\\gvim\\NERD_tree_1', 'StartPosition': {'...

  File "D:\\gvim\\vimfiles\\myplug\\ECY_new\\python/server/Main_server.py", line 241, in Pass2Hanlder
    raise

RuntimeError: No active exception to reraise
Main_server.py 185 Handler DEBUG => exception:
Traceback (most recent call last):
  File "C:\Users\qwe\AppData\Local\Programs\Python\Python37-32\lib\threading.py", line 885, in _bootstrap
    self._bootstrap_inner()
    ©¦    ©¸ <function Thread._bootstrap_inner at 0x03128108>
    ©¸ <Thread(Thread-2, started daemon 31648)>
  File "C:\Users\qwe\AppData\Local\Programs\Python\Python37-32\lib\threading.py", line 917, in _bootstrap_inner
    self.run()
    ©¦    ©¸ <function Thread.run at 0x03124FA8>
    ©¸ <Thread(Thread-2, started daemon 31648)>
  File "C:\Users\qwe\AppData\Local\Programs\Python\Python37-32\lib\threading.py", line 865, in run
    self._target(*self._args, **self._kwargs)
    ©¦    ©¦        ©¦    ©¦        ©¦    ©¸ {}
    ©¦    ©¦        ©¦    ©¦        ©¸ <Thread(Thread-2, started daemon 31648)>
    ©¦    ©¦        ©¦    ©¸ ()
    ©¦    ©¦        ©¸ <Thread(Thread-2, started daemon 31648)>
    ©¦    ©¸ <bound method GetTodo.Handler of <__main__.GetTodo object at 0x02FAA5D0>>
    ©¸ <Thread(Thread-2, started daemon 31648)>

> File "D:\\gvim\\vimfiles\\myplug\\ECY_new\\python/server/Main_server.py", line 180, in Handler
    todo_dict = self.event_handler.Pass2Hanlder(todo_dict)
    ©¦           ©¦    ©¦             ©¦            ©¸ {'Msg': {'AllTextList': '\n', 'CurrentLineText': '', 'FileType': 'nerdtree', 'FilePath': 'D:\\gvim\\NERD_tree_1', 'StartPosit...
    ©¦           ©¦    ©¦             ©¸ <function EventHandler.Pass2Hanlder at 0x0324A4B0>
    ©¦           ©¦    ©¸ <__main__.EventHandler object at 0x0329B730>
    ©¦           ©¸ <__main__.GetTodo object at 0x02FAA5D0>
    ©¸ {'Msg': {'AllTextList': '\n', 'CurrentLineText': '', 'FileType': 'nerdtree', 'FilePath': 'D:\\gvim\\NERD_tree_1', 'StartPosit...

  File "D:\\gvim\\vimfiles\\myplug\\ECY_new\\python/server/Main_server.py", line 241, in Pass2Hanlder
    raise

RuntimeError: No active exception to reraise

Traceback (most recent call last):
  File "C:\Users\qwe\AppData\Local\Programs\Python\Python37-32\lib\threading.py", line 885, in _bootstrap
    self._bootstrap_inner()
    ©¦    ©¸ <function Thread._bootstrap_inner at 0x03128108>
    ©¸ <Thread(Thread-2, started daemon 31648)>
  File "C:\Users\qwe\AppData\Local\Programs\Python\Python37-32\lib\threading.py", line 917, in _bootstrap_inner
    self.run()
    ©¦    ©¸ <function Thread.run at 0x03124FA8>
    ©¸ <Thread(Thread-2, started daemon 31648)>
  File "C:\Users\qwe\AppData\Local\Programs\Python\Python37-32\lib\threading.py", line 865, in run
    self._target(*self._args, **self._kwargs)
    ©¦    ©¦        ©¦    ©¦        ©¦    ©¸ {}
    ©¦    ©¦        ©¦    ©¦        ©¸ <Thread(Thread-2, started daemon 31648)>
    ©¦    ©¦        ©¦    ©¸ ()
    ©¦    ©¦        ©¸ <Thread(Thread-2, started daemon 31648)>
    ©¦    ©¸ <bound method GetTodo.Handler of <__main__.GetTodo object at 0x02FAA5D0>>
    ©¸ <Thread(Thread-2, started daemon 31648)>

> File "D:\\gvim\\vimfiles\\myplug\\ECY_new\\python/server/Main_server.py", line 180, in Handler
    todo_dict = self.event_handler.Pass2Hanlder(todo_dict)
    ©¦           ©¦    ©¦             ©¦            ©¸ {'Msg': {'AllTextList': '\n', 'CurrentLineText': '', 'FileType': 'nerdtree', 'FilePath': 'D:\\gvim\\NERD_tree_1', 'StartPosit...
    ©¦           ©¦    ©¦             ©¸ <function EventHandler.Pass2Hanlder at 0x0324A4B0>
    ©¦           ©¦    ©¸ <__main__.EventHandler object at 0x0329B730>
    ©¦           ©¸ <__main__.GetTodo object at 0x02FAA5D0>
    ©¸ {'Msg': {'AllTextList': '\n', 'CurrentLineText': '', 'FileType': 'nerdtree', 'FilePath': 'D:\\gvim\\NERD_tree_1', 'StartPosit...

  File "D:\\gvim\\vimfiles\\myplug\\ECY_new\\python/server/Main_server.py", line 241, in Pass2Hanlder
    raise

RuntimeError: No active exception to reraise
Main_server.py 185 Handler DEBUG => exception:
Traceback (most recent call last):
  File "C:\Users\qwe\AppData\Local\Programs\Python\Python37-32\lib\threading.py", line 885, in _bootstrap
    self._bootstrap_inner()
    ©¦    ©¸ <function Thread._bootstrap_inner at 0x03128108>
    ©¸ <Thread(Thread-2, started daemon 31648)>
  File "C:\Users\qwe\AppData\Local\Programs\Python\Python37-32\lib\threading.py", line 917, in _bootstrap_inner
    self.run()
    ©¦    ©¸ <function Thread.run at 0x03124FA8>
    ©¸ <Thread(Thread-2, started daemon 31648)>
  File "C:\Users\qwe\AppData\Local\Programs\Python\Python37-32\lib\threading.py", line 865, in run
    self._target(*self._args, **self._kwargs)
    ©¦    ©¦        ©¦    ©¦        ©¦    ©¸ {}
    ©¦    ©¦        ©¦    ©¦        ©¸ <Thread(Thread-2, started daemon 31648)>
    ©¦    ©¦        ©¦    ©¸ ()
    ©¦    ©¦        ©¸ <Thread(Thread-2, started daemon 31648)>
    ©¦    ©¸ <bound method GetTodo.Handler of <__main__.GetTodo object at 0x02FAA5D0>>
    ©¸ <Thread(Thread-2, started daemon 31648)>

> File "D:\\gvim\\vimfiles\\myplug\\ECY_new\\python/server/Main_server.py", line 180, in Handler
    todo_dict = self.event_handler.Pass2Hanlder(todo_dict)
    ©¦           ©¦    ©¦             ©¦            ©¸ {'Msg': {'TriggerLength': '1', 'ReturnMatchPoint': True, 'AllTextList': '" Press ? for help\n\n.. (up a dir)\n</myplug/ECY_ne...
    ©¦           ©¦    ©¦             ©¸ <function EventHandler.Pass2Hanlder at 0x0324A4B0>
    ©¦           ©¦    ©¸ <__main__.EventHandler object at 0x0329B730>
    ©¦           ©¸ <__main__.GetTodo object at 0x02FAA5D0>
    ©¸ {'Msg': {'TriggerLength': '1', 'ReturnMatchPoint': True, 'AllTextList': '" Press ? for help\n\n.. (up a dir)\n</myplug/ECY_ne...

  File "D:\\gvim\\vimfiles\\myplug\\ECY_new\\python/server/Main_server.py", line 241, in Pass2Hanlder
    raise

RuntimeError: No active exception to reraise

Traceback (most recent call last):
  File "C:\Users\qwe\AppData\Local\Programs\Python\Python37-32\lib\threading.py", line 885, in _bootstrap
    self._bootstrap_inner()
    ©¦    ©¸ <function Thread._bootstrap_inner at 0x03128108>
    ©¸ <Thread(Thread-2, started daemon 31648)>
  File "C:\Users\qwe\AppData\Local\Programs\Python\Python37-32\lib\threading.py", line 917, in _bootstrap_inner
    self.run()
    ©¦    ©¸ <function Thread.run at 0x03124FA8>
    ©¸ <Thread(Thread-2, started daemon 31648)>
  File "C:\Users\qwe\AppData\Local\Programs\Python\Python37-32\lib\threading.py", line 865, in run
    self._target(*self._args, **self._kwargs)
    ©¦    ©¦        ©¦    ©¦        ©¦    ©¸ {}
    ©¦    ©¦        ©¦    ©¦        ©¸ <Thread(Thread-2, started daemon 31648)>
    ©¦    ©¦        ©¦    ©¸ ()
    ©¦    ©¦        ©¸ <Thread(Thread-2, started daemon 31648)>
    ©¦    ©¸ <bound method GetTodo.Handler of <__main__.GetTodo object at 0x02FAA5D0>>
    ©¸ <Thread(Thread-2, started daemon 31648)>

> File "D:\\gvim\\vimfiles\\myplug\\ECY_new\\python/server/Main_server.py", line 180, in Handler
    todo_dict = self.event_handler.Pass2Hanlder(todo_dict)
    ©¦           ©¦    ©¦             ©¦            ©¸ {'Msg': {'TriggerLength': '1', 'ReturnMatchPoint': True, 'AllTextList': '" Press ? for help\n\n.. (up a dir)\n</myplug/ECY_ne...
    ©¦           ©¦    ©¦             ©¸ <function EventHandler.Pass2Hanlder at 0x0324A4B0>
    ©¦           ©¦    ©¸ <__main__.EventHandler object at 0x0329B730>
    ©¦           ©¸ <__main__.GetTodo object at 0x02FAA5D0>
    ©¸ {'Msg': {'TriggerLength': '1', 'ReturnMatchPoint': True, 'AllTextList': '" Press ? for help\n\n.. (up a dir)\n</myplug/ECY_ne...

  File "D:\\gvim\\vimfiles\\myplug\\ECY_new\\python/server/Main_server.py", line 241, in Pass2Hanlder
    raise

RuntimeError: No active exception to reraise
Main_server.py 185 Handler DEBUG => exception:
Traceback (most recent call last):
  File "C:\Users\qwe\AppData\Local\Programs\Python\Python37-32\lib\threading.py", line 885, in _bootstrap
    self._bootstrap_inner()
    ©¦    ©¸ <function Thread._bootstrap_inner at 0x03128108>
    ©¸ <Thread(Thread-2, started daemon 31648)>
  File "C:\Users\qwe\AppData\Local\Programs\Python\Python37-32\lib\threading.py", line 917, in _bootstrap_inner
    self.run()
    ©¦    ©¸ <function Thread.run at 0x03124FA8>
    ©¸ <Thread(Thread-2, started daemon 31648)>
  File "C:\Users\qwe\AppData\Local\Programs\Python\Python37-32\lib\threading.py", line 865, in run
    self._target(*self._args, **self._kwargs)
    ©¦    ©¦        ©¦    ©¦        ©¦    ©¸ {}
    ©¦    ©¦        ©¦    ©¦        ©¸ <Thread(Thread-2, started daemon 31648)>
    ©¦    ©¦        ©¦    ©¸ ()
    ©¦    ©¦        ©¸ <Thread(Thread-2, started daemon 31648)>
    ©¦    ©¸ <bound method GetTodo.Handler of <__main__.GetTodo object at 0x02FAA5D0>>
    ©¸ <Thread(Thread-2, started daemon 31648)>

> File "D:\\gvim\\vimfiles\\myplug\\ECY_new\\python/server/Main_server.py", line 180, in Handler
    todo_dict = self.event_handler.Pass2Hanlder(todo_dict)
    ©¦           ©¦    ©¦             ©¦            ©¸ {'Msg': {'TriggerLength': '1', 'ReturnMatchPoint': True, 'AllTextList': '" Press ? for help\n\n.. (up a dir)\n/gvim/vimfiles/...
    ©¦           ©¦    ©¦             ©¸ <function EventHandler.Pass2Hanlder at 0x0324A4B0>
    ©¦           ©¦    ©¸ <__main__.EventHandler object at 0x0329B730>
    ©¦           ©¸ <__main__.GetTodo object at 0x02FAA5D0>
    ©¸ {'Msg': {'TriggerLength': '1', 'ReturnMatchPoint': True, 'AllTextList': '" Press ? for help\n\n.. (up a dir)\n/gvim/vimfiles/...

  File "D:\\gvim\\vimfiles\\myplug\\ECY_new\\python/server/Main_server.py", line 241, in Pass2Hanlder
    raise

RuntimeError: No active exception to reraise

Traceback (most recent call last):
  File "C:\Users\qwe\AppData\Local\Programs\Python\Python37-32\lib\threading.py", line 885, in _bootstrap
    self._bootstrap_inner()
    ©¦    ©¸ <function Thread._bootstrap_inner at 0x03128108>
    ©¸ <Thread(Thread-2, started daemon 31648)>
  File "C:\Users\qwe\AppData\Local\Programs\Python\Python37-32\lib\threading.py", line 917, in _bootstrap_inner
    self.run()
    ©¦    ©¸ <function Thread.run at 0x03124FA8>
    ©¸ <Thread(Thread-2, started daemon 31648)>
  File "C:\Users\qwe\AppData\Local\Programs\Python\Python37-32\lib\threading.py", line 865, in run
    self._target(*self._args, **self._kwargs)
    ©¦    ©¦        ©¦    ©¦        ©¦    ©¸ {}
    ©¦    ©¦        ©¦    ©¦        ©¸ <Thread(Thread-2, started daemon 31648)>
    ©¦    ©¦        ©¦    ©¸ ()
    ©¦    ©¦        ©¸ <Thread(Thread-2, started daemon 31648)>
    ©¦    ©¸ <bound method GetTodo.Handler of <__main__.GetTodo object at 0x02FAA5D0>>
    ©¸ <Thread(Thread-2, started daemon 31648)>

> File "D:\\gvim\\vimfiles\\myplug\\ECY_new\\python/server/Main_server.py", line 180, in Handler
    todo_dict = self.event_handler.Pass2Hanlder(todo_dict)
    ©¦           ©¦    ©¦             ©¦            ©¸ {'Msg': {'TriggerLength': '1', 'ReturnMatchPoint': True, 'AllTextList': '" Press ? for help\n\n.. (up a dir)\n/gvim/vimfiles/...
    ©¦           ©¦    ©¦             ©¸ <function EventHandler.Pass2Hanlder at 0x0324A4B0>
    ©¦           ©¦    ©¸ <__main__.EventHandler object at 0x0329B730>
    ©¦           ©¸ <__main__.GetTodo object at 0x02FAA5D0>
    ©¸ {'Msg': {'TriggerLength': '1', 'ReturnMatchPoint': True, 'AllTextList': '" Press ? for help\n\n.. (up a dir)\n/gvim/vimfiles/...

  File "D:\\gvim\\vimfiles\\myplug\\ECY_new\\python/server/Main_server.py", line 241, in Pass2Hanlder
    raise

RuntimeError: No active exception to reraise
Main_server.py 185 Handler DEBUG => exception:
Traceback (most recent call last):
  File "C:\Users\qwe\AppData\Local\Programs\Python\Python37-32\lib\threading.py", line 885, in _bootstrap
    self._bootstrap_inner()
    ©¦    ©¸ <function Thread._bootstrap_inner at 0x03128108>
    ©¸ <Thread(Thread-2, started daemon 31648)>
  File "C:\Users\qwe\AppData\Local\Programs\Python\Python37-32\lib\threading.py", line 917, in _bootstrap_inner
    self.run()
    ©¦    ©¸ <function Thread.run at 0x03124FA8>
    ©¸ <Thread(Thread-2, started daemon 31648)>
  File "C:\Users\qwe\AppData\Local\Programs\Python\Python37-32\lib\threading.py", line 865, in run
    self._target(*self._args, **self._kwargs)
    ©¦    ©¦        ©¦    ©¦        ©¦    ©¸ {}
    ©¦    ©¦        ©¦    ©¦        ©¸ <Thread(Thread-2, started daemon 31648)>
    ©¦    ©¦        ©¦    ©¸ ()
    ©¦    ©¦        ©¸ <Thread(Thread-2, started daemon 31648)>
    ©¦    ©¸ <bound method GetTodo.Handler of <__main__.GetTodo object at 0x02FAA5D0>>
    ©¸ <Thread(Thread-2, started daemon 31648)>

> File "D:\\gvim\\vimfiles\\myplug\\ECY_new\\python/server/Main_server.py", line 180, in Handler
    todo_dict = self.event_handler.Pass2Hanlder(todo_dict)
    ©¦           ©¦    ©¦             ©¦            ©¸ {'Msg': {'TriggerLength': '1', 'ReturnMatchPoint': True, 'AllTextList': '" Press ? for help\n\n.. (up a dir)\n/gvim/vimfiles/...
    ©¦           ©¦    ©¦             ©¸ <function EventHandler.Pass2Hanlder at 0x0324A4B0>
    ©¦           ©¦    ©¸ <__main__.EventHandler object at 0x0329B730>
    ©¦           ©¸ <__main__.GetTodo object at 0x02FAA5D0>
    ©¸ {'Msg': {'TriggerLength': '1', 'ReturnMatchPoint': True, 'AllTextList': '" Press ? for help\n\n.. (up a dir)\n/gvim/vimfiles/...

  File "D:\\gvim\\vimfiles\\myplug\\ECY_new\\python/server/Main_server.py", line 241, in Pass2Hanlder
    raise

RuntimeError: No active exception to reraise

Traceback (most recent call last):
  File "C:\Users\qwe\AppData\Local\Programs\Python\Python37-32\lib\threading.py", line 885, in _bootstrap
    self._bootstrap_inner()
    ©¦    ©¸ <function Thread._bootstrap_inner at 0x03128108>
    ©¸ <Thread(Thread-2, started daemon 31648)>
  File "C:\Users\qwe\AppData\Local\Programs\Python\Python37-32\lib\threading.py", line 917, in _bootstrap_inner
    self.run()
    ©¦    ©¸ <function Thread.run at 0x03124FA8>
    ©¸ <Thread(Thread-2, started daemon 31648)>
  File "C:\Users\qwe\AppData\Local\Programs\Python\Python37-32\lib\threading.py", line 865, in run
    self._target(*self._args, **self._kwargs)
    ©¦    ©¦        ©¦    ©¦        ©¦    ©¸ {}
    ©¦    ©¦        ©¦    ©¦        ©¸ <Thread(Thread-2, started daemon 31648)>
    ©¦    ©¦        ©¦    ©¸ ()
    ©¦    ©¦        ©¸ <Thread(Thread-2, started daemon 31648)>
    ©¦    ©¸ <bound method GetTodo.Handler of <__main__.GetTodo object at 0x02FAA5D0>>
    ©¸ <Thread(Thread-2, started daemon 31648)>

> File "D:\\gvim\\vimfiles\\myplug\\ECY_new\\python/server/Main_server.py", line 180, in Handler
    todo_dict = self.event_handler.Pass2Hanlder(todo_dict)
    ©¦           ©¦    ©¦             ©¦            ©¸ {'Msg': {'TriggerLength': '1', 'ReturnMatchPoint': True, 'AllTextList': '" Press ? for help\n\n.. (up a dir)\n/gvim/vimfiles/...
    ©¦           ©¦    ©¦             ©¸ <function EventHandler.Pass2Hanlder at 0x0324A4B0>
    ©¦           ©¦    ©¸ <__main__.EventHandler object at 0x0329B730>
    ©¦           ©¸ <__main__.GetTodo object at 0x02FAA5D0>
    ©¸ {'Msg': {'TriggerLength': '1', 'ReturnMatchPoint': True, 'AllTextList': '" Press ? for help\n\n.. (up a dir)\n/gvim/vimfiles/...

  File "D:\\gvim\\vimfiles\\myplug\\ECY_new\\python/server/Main_server.py", line 241, in Pass2Hanlder
    raise

RuntimeError: No active exception to reraise
Main_server.py 185 Handler DEBUG => exception:
Traceback (most recent call last):
  File "C:\Users\qwe\AppData\Local\Programs\Python\Python37-32\lib\threading.py", line 885, in _bootstrap
    self._bootstrap_inner()
    ©¦    ©¸ <function Thread._bootstrap_inner at 0x03128108>
    ©¸ <Thread(Thread-2, started daemon 31648)>
  File "C:\Users\qwe\AppData\Local\Programs\Python\Python37-32\lib\threading.py", line 917, in _bootstrap_inner
    self.run()
    ©¦    ©¸ <function Thread.run at 0x03124FA8>
    ©¸ <Thread(Thread-2, started daemon 31648)>
  File "C:\Users\qwe\AppData\Local\Programs\Python\Python37-32\lib\threading.py", line 865, in run
    self._target(*self._args, **self._kwargs)
    ©¦    ©¦        ©¦    ©¦        ©¦    ©¸ {}
    ©¦    ©¦        ©¦    ©¦        ©¸ <Thread(Thread-2, started daemon 31648)>
    ©¦    ©¦        ©¦    ©¸ ()
    ©¦    ©¦        ©¸ <Thread(Thread-2, started daemon 31648)>
    ©¦    ©¸ <bound method GetTodo.Handler of <__main__.GetTodo object at 0x02FAA5D0>>
    ©¸ <Thread(Thread-2, started daemon 31648)>

> File "D:\\gvim\\vimfiles\\myplug\\ECY_new\\python/server/Main_server.py", line 180, in Handler
    todo_dict = self.event_handler.Pass2Hanlder(todo_dict)
    ©¦           ©¦    ©¦             ©¦            ©¸ {'Msg': {'TriggerLength': '1', 'ReturnMatchPoint': True, 'AllTextList': '" Press ? for help\n\n.. (up a dir)\n/gvim/vimfiles/...
    ©¦           ©¦    ©¦             ©¸ <function EventHandler.Pass2Hanlder at 0x0324A4B0>
    ©¦           ©¦    ©¸ <__main__.EventHandler object at 0x0329B730>
    ©¦           ©¸ <__main__.GetTodo object at 0x02FAA5D0>
    ©¸ {'Msg': {'TriggerLength': '1', 'ReturnMatchPoint': True, 'AllTextList': '" Press ? for help\n\n.. (up a dir)\n/gvim/vimfiles/...

  File "D:\\gvim\\vimfiles\\myplug\\ECY_new\\python/server/Main_server.py", line 241, in Pass2Hanlder
    raise

RuntimeError: No active exception to reraise

Traceback (most recent call last):
  File "C:\Users\qwe\AppData\Local\Programs\Python\Python37-32\lib\threading.py", line 885, in _bootstrap
    self._bootstrap_inner()
    ©¦    ©¸ <function Thread._bootstrap_inner at 0x03128108>
    ©¸ <Thread(Thread-2, started daemon 31648)>
  File "C:\Users\qwe\AppData\Local\Programs\Python\Python37-32\lib\threading.py", line 917, in _bootstrap_inner
    self.run()
    ©¦    ©¸ <function Thread.run at 0x03124FA8>
    ©¸ <Thread(Thread-2, started daemon 31648)>
  File "C:\Users\qwe\AppData\Local\Programs\Python\Python37-32\lib\threading.py", line 865, in run
    self._target(*self._args, **self._kwargs)
    ©¦    ©¦        ©¦    ©¦        ©¦    ©¸ {}
    ©¦    ©¦        ©¦    ©¦        ©¸ <Thread(Thread-2, started daemon 31648)>
    ©¦    ©¦        ©¦    ©¸ ()
    ©¦    ©¦        ©¸ <Thread(Thread-2, started daemon 31648)>
    ©¦    ©¸ <bound method GetTodo.Handler of <__main__.GetTodo object at 0x02FAA5D0>>
    ©¸ <Thread(Thread-2, started daemon 31648)>

> File "D:\\gvim\\vimfiles\\myplug\\ECY_new\\python/server/Main_server.py", line 180, in Handler
    todo_dict = self.event_handler.Pass2Hanlder(todo_dict)
    ©¦           ©¦    ©¦             ©¦            ©¸ {'Msg': {'TriggerLength': '1', 'ReturnMatchPoint': True, 'AllTextList': '" Press ? for help\n\n.. (up a dir)\n/gvim/vimfiles/...
    ©¦           ©¦    ©¦             ©¸ <function EventHandler.Pass2Hanlder at 0x0324A4B0>
    ©¦           ©¦    ©¸ <__main__.EventHandler object at 0x0329B730>
    ©¦           ©¸ <__main__.GetTodo object at 0x02FAA5D0>
    ©¸ {'Msg': {'TriggerLength': '1', 'ReturnMatchPoint': True, 'AllTextList': '" Press ? for help\n\n.. (up a dir)\n/gvim/vimfiles/...

  File "D:\\gvim\\vimfiles\\myplug\\ECY_new\\python/server/Main_server.py", line 241, in Pass2Hanlder
    raise

RuntimeError: No active exception to reraise
Main_server.py 185 Handler DEBUG => exception:
Traceback (most recent call last):
  File "C:\Users\qwe\AppData\Local\Programs\Python\Python37-32\lib\threading.py", line 885, in _bootstrap
    self._bootstrap_inner()
    ©¦    ©¸ <function Thread._bootstrap_inner at 0x03128108>
    ©¸ <Thread(Thread-2, started daemon 31648)>
  File "C:\Users\qwe\AppData\Local\Programs\Python\Python37-32\lib\threading.py", line 917, in _bootstrap_inner
    self.run()
    ©¦    ©¸ <function Thread.run at 0x03124FA8>
    ©¸ <Thread(Thread-2, started daemon 31648)>
  File "C:\Users\qwe\AppData\Local\Programs\Python\Python37-32\lib\threading.py", line 865, in run
    self._target(*self._args, **self._kwargs)
    ©¦    ©¦        ©¦    ©¦        ©¦    ©¸ {}
    ©¦    ©¦        ©¦    ©¦        ©¸ <Thread(Thread-2, started daemon 31648)>
    ©¦    ©¦        ©¦    ©¸ ()
    ©¦    ©¦        ©¸ <Thread(Thread-2, started daemon 31648)>
    ©¦    ©¸ <bound method GetTodo.Handler of <__main__.GetTodo object at 0x02FAA5D0>>
    ©¸ <Thread(Thread-2, started daemon 31648)>

> File "D:\\gvim\\vimfiles\\myplug\\ECY_new\\python/server/Main_server.py", line 180, in Handler
    todo_dict = self.event_handler.Pass2Hanlder(todo_dict)
    ©¦           ©¦    ©¦             ©¦            ©¸ {'Msg': {'TriggerLength': '1', 'ReturnMatchPoint': True, 'AllTextList': '" Press ? for help\n\n.. (up a dir)\n/gvim/vimfiles/...
    ©¦           ©¦    ©¦             ©¸ <function EventHandler.Pass2Hanlder at 0x0324A4B0>
    ©¦           ©¦    ©¸ <__main__.EventHandler object at 0x0329B730>
    ©¦           ©¸ <__main__.GetTodo object at 0x02FAA5D0>
    ©¸ {'Msg': {'TriggerLength': '1', 'ReturnMatchPoint': True, 'AllTextList': '" Press ? for help\n\n.. (up a dir)\n/gvim/vimfiles/...

  File "D:\\gvim\\vimfiles\\myplug\\ECY_new\\python/server/Main_server.py", line 241, in Pass2Hanlder
    raise

RuntimeError: No active exception to reraise

Traceback (most recent call last):
  File "C:\Users\qwe\AppData\Local\Programs\Python\Python37-32\lib\threading.py", line 885, in _bootstrap
    self._bootstrap_inner()
    ©¦    ©¸ <function Thread._bootstrap_inner at 0x03128108>
    ©¸ <Thread(Thread-2, started daemon 31648)>
  File "C:\Users\qwe\AppData\Local\Programs\Python\Python37-32\lib\threading.py", line 917, in _bootstrap_inner
    self.run()
    ©¦    ©¸ <function Thread.run at 0x03124FA8>
    ©¸ <Thread(Thread-2, started daemon 31648)>
  File "C:\Users\qwe\AppData\Local\Programs\Python\Python37-32\lib\threading.py", line 865, in run
    self._target(*self._args, **self._kwargs)
    ©¦    ©¦        ©¦    ©¦        ©¦    ©¸ {}
    ©¦    ©¦        ©¦    ©¦        ©¸ <Thread(Thread-2, started daemon 31648)>
    ©¦    ©¦        ©¦    ©¸ ()
    ©¦    ©¦        ©¸ <Thread(Thread-2, started daemon 31648)>
    ©¦    ©¸ <bound method GetTodo.Handler of <__main__.GetTodo object at 0x02FAA5D0>>
    ©¸ <Thread(Thread-2, started daemon 31648)>

> File "D:\\gvim\\vimfiles\\myplug\\ECY_new\\python/server/Main_server.py", line 180, in Handler
    todo_dict = self.event_handler.Pass2Hanlder(todo_dict)
    ©¦           ©¦    ©¦             ©¦            ©¸ {'Msg': {'TriggerLength': '1', 'ReturnMatchPoint': True, 'AllTextList': '" Press ? for help\n\n.. (up a dir)\n/gvim/vimfiles/...
    ©¦           ©¦    ©¦             ©¸ <function EventHandler.Pass2Hanlder at 0x0324A4B0>
    ©¦           ©¦    ©¸ <__main__.EventHandler object at 0x0329B730>
    ©¦           ©¸ <__main__.GetTodo object at 0x02FAA5D0>
    ©¸ {'Msg': {'TriggerLength': '1', 'ReturnMatchPoint': True, 'AllTextList': '" Press ? for help\n\n.. (up a dir)\n/gvim/vimfiles/...

  File "D:\\gvim\\vimfiles\\myplug\\ECY_new\\python/server/Main_server.py", line 241, in Pass2Hanlder
    raise

RuntimeError: No active exception to reraise
Main_server.py 185 Handler DEBUG => exception:
Traceback (most recent call last):
  File "C:\Users\qwe\AppData\Local\Programs\Python\Python37-32\lib\threading.py", line 885, in _bootstrap
    self._bootstrap_inner()
    ©¦    ©¸ <function Thread._bootstrap_inner at 0x03128108>
    ©¸ <Thread(Thread-2, started daemon 31648)>
  File "C:\Users\qwe\AppData\Local\Programs\Python\Python37-32\lib\threading.py", line 917, in _bootstrap_inner
    self.run()
    ©¦    ©¸ <function Thread.run at 0x03124FA8>
    ©¸ <Thread(Thread-2, started daemon 31648)>
  File "C:\Users\qwe\AppData\Local\Programs\Python\Python37-32\lib\threading.py", line 865, in run
    self._target(*self._args, **self._kwargs)
    ©¦    ©¦        ©¦    ©¦        ©¦    ©¸ {}
    ©¦    ©¦        ©¦    ©¦        ©¸ <Thread(Thread-2, started daemon 31648)>
    ©¦    ©¦        ©¦    ©¸ ()
    ©¦    ©¦        ©¸ <Thread(Thread-2, started daemon 31648)>
    ©¦    ©¸ <bound method GetTodo.Handler of <__main__.GetTodo object at 0x02FAA5D0>>
    ©¸ <Thread(Thread-2, started daemon 31648)>

> File "D:\\gvim\\vimfiles\\myplug\\ECY_new\\python/server/Main_server.py", line 180, in Handler
    todo_dict = self.event_handler.Pass2Hanlder(todo_dict)
    ©¦           ©¦    ©¦             ©¦            ©¸ {'Msg': {'TriggerLength': '1', 'ReturnMatchPoint': True, 'AllTextList': '" Press ? for help\n\n.. (up a dir)\n/gvim/vimfiles/...
    ©¦           ©¦    ©¦             ©¸ <function EventHandler.Pass2Hanlder at 0x0324A4B0>
    ©¦           ©¦    ©¸ <__main__.EventHandler object at 0x0329B730>
    ©¦           ©¸ <__main__.GetTodo object at 0x02FAA5D0>
    ©¸ {'Msg': {'TriggerLength': '1', 'ReturnMatchPoint': True, 'AllTextList': '" Press ? for help\n\n.. (up a dir)\n/gvim/vimfiles/...

  File "D:\\gvim\\vimfiles\\myplug\\ECY_new\\python/server/Main_server.py", line 241, in Pass2Hanlder
    raise

RuntimeError: No active exception to reraise

Traceback (most recent call last):
  File "C:\Users\qwe\AppData\Local\Programs\Python\Python37-32\lib\threading.py", line 885, in _bootstrap
    self._bootstrap_inner()
    ©¦    ©¸ <function Thread._bootstrap_inner at 0x03128108>
    ©¸ <Thread(Thread-2, started daemon 31648)>
  File "C:\Users\qwe\AppData\Local\Programs\Python\Python37-32\lib\threading.py", line 917, in _bootstrap_inner
    self.run()
    ©¦    ©¸ <function Thread.run at 0x03124FA8>
    ©¸ <Thread(Thread-2, started daemon 31648)>
  File "C:\Users\qwe\AppData\Local\Programs\Python\Python37-32\lib\threading.py", line 865, in run
    self._target(*self._args, **self._kwargs)
    ©¦    ©¦        ©¦    ©¦        ©¦    ©¸ {}
    ©¦    ©¦        ©¦    ©¦        ©¸ <Thread(Thread-2, started daemon 31648)>
    ©¦    ©¦        ©¦    ©¸ ()
    ©¦    ©¦        ©¸ <Thread(Thread-2, started daemon 31648)>
    ©¦    ©¸ <bound method GetTodo.Handler of <__main__.GetTodo object at 0x02FAA5D0>>
    ©¸ <Thread(Thread-2, started daemon 31648)>

> File "D:\\gvim\\vimfiles\\myplug\\ECY_new\\python/server/Main_server.py", line 180, in Handler
    todo_dict = self.event_handler.Pass2Hanlder(todo_dict)
    ©¦           ©¦    ©¦             ©¦            ©¸ {'Msg': {'TriggerLength': '1', 'ReturnMatchPoint': True, 'AllTextList': '" Press ? for help\n\n.. (up a dir)\n/gvim/vimfiles/...
    ©¦           ©¦    ©¦             ©¸ <function EventHandler.Pass2Hanlder at 0x0324A4B0>
    ©¦           ©¦    ©¸ <__main__.EventHandler object at 0x0329B730>
    ©¦           ©¸ <__main__.GetTodo object at 0x02FAA5D0>
    ©¸ {'Msg': {'TriggerLength': '1', 'ReturnMatchPoint': True, 'AllTextList': '" Press ? for help\n\n.. (up a dir)\n/gvim/vimfiles/...

  File "D:\\gvim\\vimfiles\\myplug\\ECY_new\\python/server/Main_server.py", line 241, in Pass2Hanlder
    raise

RuntimeError: No active exception to reraise
Main_server.py 185 Handler DEBUG => exception:
Traceback (most recent call last):
  File "C:\Users\qwe\AppData\Local\Programs\Python\Python37-32\lib\threading.py", line 885, in _bootstrap
    self._bootstrap_inner()
    ©¦    ©¸ <function Thread._bootstrap_inner at 0x03128108>
    ©¸ <Thread(Thread-2, started daemon 31648)>
  File "C:\Users\qwe\AppData\Local\Programs\Python\Python37-32\lib\threading.py", line 917, in _bootstrap_inner
    self.run()
    ©¦    ©¸ <function Thread.run at 0x03124FA8>
    ©¸ <Thread(Thread-2, started daemon 31648)>
  File "C:\Users\qwe\AppData\Local\Programs\Python\Python37-32\lib\threading.py", line 865, in run
    self._target(*self._args, **self._kwargs)
    ©¦    ©¦        ©¦    ©¦        ©¦    ©¸ {}
    ©¦    ©¦        ©¦    ©¦        ©¸ <Thread(Thread-2, started daemon 31648)>
    ©¦    ©¦        ©¦    ©¸ ()
    ©¦    ©¦        ©¸ <Thread(Thread-2, started daemon 31648)>
    ©¦    ©¸ <bound method GetTodo.Handler of <__main__.GetTodo object at 0x02FAA5D0>>
    ©¸ <Thread(Thread-2, started daemon 31648)>

> File "D:\\gvim\\vimfiles\\myplug\\ECY_new\\python/server/Main_server.py", line 180, in Handler
    todo_dict = self.event_handler.Pass2Hanlder(todo_dict)
    ©¦           ©¦    ©¦             ©¦            ©¸ {'Msg': {'TriggerLength': '1', 'ReturnMatchPoint': True, 'AllTextList': '" Press ? for help\n\n.. (up a dir)\n/gvim/vimfiles/...
    ©¦           ©¦    ©¦             ©¸ <function EventHandler.Pass2Hanlder at 0x0324A4B0>
    ©¦           ©¦    ©¸ <__main__.EventHandler object at 0x0329B730>
    ©¦           ©¸ <__main__.GetTodo object at 0x02FAA5D0>
    ©¸ {'Msg': {'TriggerLength': '1', 'ReturnMatchPoint': True, 'AllTextList': '" Press ? for help\n\n.. (up a dir)\n/gvim/vimfiles/...

  File "D:\\gvim\\vimfiles\\myplug\\ECY_new\\python/server/Main_server.py", line 241, in Pass2Hanlder
    raise

RuntimeError: No active exception to reraise

Traceback (most recent call last):
  File "C:\Users\qwe\AppData\Local\Programs\Python\Python37-32\lib\threading.py", line 885, in _bootstrap
    self._bootstrap_inner()
    ©¦    ©¸ <function Thread._bootstrap_inner at 0x03128108>
    ©¸ <Thread(Thread-2, started daemon 31648)>
  File "C:\Users\qwe\AppData\Local\Programs\Python\Python37-32\lib\threading.py", line 917, in _bootstrap_inner
    self.run()
    ©¦    ©¸ <function Thread.run at 0x03124FA8>
    ©¸ <Thread(Thread-2, started daemon 31648)>
  File "C:\Users\qwe\AppData\Local\Programs\Python\Python37-32\lib\threading.py", line 865, in run
    self._target(*self._args, **self._kwargs)
    ©¦    ©¦        ©¦    ©¦        ©¦    ©¸ {}
    ©¦    ©¦        ©¦    ©¦        ©¸ <Thread(Thread-2, started daemon 31648)>
    ©¦    ©¦        ©¦    ©¸ ()
    ©¦    ©¦        ©¸ <Thread(Thread-2, started daemon 31648)>
    ©¦    ©¸ <bound method GetTodo.Handler of <__main__.GetTodo object at 0x02FAA5D0>>
    ©¸ <Thread(Thread-2, started daemon 31648)>

> File "D:\\gvim\\vimfiles\\myplug\\ECY_new\\python/server/Main_server.py", line 180, in Handler
    todo_dict = self.event_handler.Pass2Hanlder(todo_dict)
    ©¦           ©¦    ©¦             ©¦            ©¸ {'Msg': {'TriggerLength': '1', 'ReturnMatchPoint': True, 'AllTextList': '" Press ? for help\n\n.. (up a dir)\n/gvim/vimfiles/...
    ©¦           ©¦    ©¦             ©¸ <function EventHandler.Pass2Hanlder at 0x0324A4B0>
    ©¦           ©¦    ©¸ <__main__.EventHandler object at 0x0329B730>
    ©¦           ©¸ <__main__.GetTodo object at 0x02FAA5D0>
    ©¸ {'Msg': {'TriggerLength': '1', 'ReturnMatchPoint': True, 'AllTextList': '" Press ? for help\n\n.. (up a dir)\n/gvim/vimfiles/...

  File "D:\\gvim\\vimfiles\\myplug\\ECY_new\\python/server/Main_server.py", line 241, in Pass2Hanlder
    raise

RuntimeError: No active exception to reraise
Main_server.py 185 Handler DEBUG => exception:
Traceback (most recent call last):
  File "C:\Users\qwe\AppData\Local\Programs\Python\Python37-32\lib\threading.py", line 885, in _bootstrap
    self._bootstrap_inner()
    ©¦    ©¸ <function Thread._bootstrap_inner at 0x03128108>
    ©¸ <Thread(Thread-2, started daemon 31648)>
  File "C:\Users\qwe\AppData\Local\Programs\Python\Python37-32\lib\threading.py", line 917, in _bootstrap_inner
    self.run()
    ©¦    ©¸ <function Thread.run at 0x03124FA8>
    ©¸ <Thread(Thread-2, started daemon 31648)>
  File "C:\Users\qwe\AppData\Local\Programs\Python\Python37-32\lib\threading.py", line 865, in run
    self._target(*self._args, **self._kwargs)
    ©¦    ©¦        ©¦    ©¦        ©¦    ©¸ {}
    ©¦    ©¦        ©¦    ©¦        ©¸ <Thread(Thread-2, started daemon 31648)>
    ©¦    ©¦        ©¦    ©¸ ()
    ©¦    ©¦        ©¸ <Thread(Thread-2, started daemon 31648)>
    ©¦    ©¸ <bound method GetTodo.Handler of <__main__.GetTodo object at 0x02FAA5D0>>
    ©¸ <Thread(Thread-2, started daemon 31648)>

> File "D:\\gvim\\vimfiles\\myplug\\ECY_new\\python/server/Main_server.py", line 180, in Handler
    todo_dict = self.event_handler.Pass2Hanlder(todo_dict)
    ©¦           ©¦    ©¦             ©¦            ©¸ {'Msg': {'AllTextList': '[installed_completor]\nserver_lib.sources.label.Label = label\nserver_lib.sources.python.python = py...
    ©¦           ©¦    ©¦             ©¸ <function EventHandler.Pass2Hanlder at 0x0324A4B0>
    ©¦           ©¦    ©¸ <__main__.EventHandler object at 0x0329B730>
    ©¦           ©¸ <__main__.GetTodo object at 0x02FAA5D0>
    ©¸ {'Msg': {'AllTextList': '[installed_completor]\nserver_lib.sources.label.Label = label\nserver_lib.sources.python.python = py...

  File "D:\\gvim\\vimfiles\\myplug\\ECY_new\\python/server/Main_server.py", line 241, in Pass2Hanlder
    raise

RuntimeError: No active exception to reraise

Traceback (most recent call last):
  File "C:\Users\qwe\AppData\Local\Programs\Python\Python37-32\lib\threading.py", line 885, in _bootstrap
    self._bootstrap_inner()
    ©¦    ©¸ <function Thread._bootstrap_inner at 0x03128108>
    ©¸ <Thread(Thread-2, started daemon 31648)>
  File "C:\Users\qwe\AppData\Local\Programs\Python\Python37-32\lib\threading.py", line 917, in _bootstrap_inner
    self.run()
    ©¦    ©¸ <function Thread.run at 0x03124FA8>
    ©¸ <Thread(Thread-2, started daemon 31648)>
  File "C:\Users\qwe\AppData\Local\Programs\Python\Python37-32\lib\threading.py", line 865, in run
    self._target(*self._args, **self._kwargs)
    ©¦    ©¦        ©¦    ©¦        ©¦    ©¸ {}
    ©¦    ©¦        ©¦    ©¦        ©¸ <Thread(Thread-2, started daemon 31648)>
    ©¦    ©¦        ©¦    ©¸ ()
    ©¦    ©¦        ©¸ <Thread(Thread-2, started daemon 31648)>
    ©¦    ©¸ <bound method GetTodo.Handler of <__main__.GetTodo object at 0x02FAA5D0>>
    ©¸ <Thread(Thread-2, started daemon 31648)>

> File "D:\\gvim\\vimfiles\\myplug\\ECY_new\\python/server/Main_server.py", line 180, in Handler
    todo_dict = self.event_handler.Pass2Hanlder(todo_dict)
    ©¦           ©¦    ©¦             ©¦            ©¸ {'Msg': {'AllTextList': '[installed_completor]\nserver_lib.sources.label.Label = label\nserver_lib.sources.python.python = py...
    ©¦           ©¦    ©¦             ©¸ <function EventHandler.Pass2Hanlder at 0x0324A4B0>
    ©¦           ©¦    ©¸ <__main__.EventHandler object at 0x0329B730>
    ©¦           ©¸ <__main__.GetTodo object at 0x02FAA5D0>
    ©¸ {'Msg': {'AllTextList': '[installed_completor]\nserver_lib.sources.label.Label = label\nserver_lib.sources.python.python = py...

  File "D:\\gvim\\vimfiles\\myplug\\ECY_new\\python/server/Main_server.py", line 241, in Pass2Hanlder
    raise

RuntimeError: No active exception to reraise
Main_server.py 185 Handler DEBUG => exception:
Traceback (most recent call last):
  File "C:\Users\qwe\AppData\Local\Programs\Python\Python37-32\lib\threading.py", line 885, in _bootstrap
    self._bootstrap_inner()
    ©¦    ©¸ <function Thread._bootstrap_inner at 0x03128108>
    ©¸ <Thread(Thread-2, started daemon 31648)>
  File "C:\Users\qwe\AppData\Local\Programs\Python\Python37-32\lib\threading.py", line 917, in _bootstrap_inner
    self.run()
    ©¦    ©¸ <function Thread.run at 0x03124FA8>
    ©¸ <Thread(Thread-2, started daemon 31648)>
  File "C:\Users\qwe\AppData\Local\Programs\Python\Python37-32\lib\threading.py", line 865, in run
    self._target(*self._args, **self._kwargs)
    ©¦    ©¦        ©¦    ©¦        ©¦    ©¸ {}
    ©¦    ©¦        ©¦    ©¦        ©¸ <Thread(Thread-2, started daemon 31648)>
    ©¦    ©¦        ©¦    ©¸ ()
    ©¦    ©¦        ©¸ <Thread(Thread-2, started daemon 31648)>
    ©¦    ©¸ <bound method GetTodo.Handler of <__main__.GetTodo object at 0x02FAA5D0>>
    ©¸ <Thread(Thread-2, started daemon 31648)>

> File "D:\\gvim\\vimfiles\\myplug\\ECY_new\\python/server/Main_server.py", line 180, in Handler
    todo_dict = self.event_handler.Pass2Hanlder(todo_dict)
    ©¦           ©¦    ©¦             ©¦            ©¸ {'Msg': {'AllTextList': '[installed_completor]\nserver_lib.sources.label.Label = label\nserver_lib.sources.python.python = py...
    ©¦           ©¦    ©¦             ©¸ <function EventHandler.Pass2Hanlder at 0x0324A4B0>
    ©¦           ©¦    ©¸ <__main__.EventHandler object at 0x0329B730>
    ©¦           ©¸ <__main__.GetTodo object at 0x02FAA5D0>
    ©¸ {'Msg': {'AllTextList': '[installed_completor]\nserver_lib.sources.label.Label = label\nserver_lib.sources.python.python = py...

  File "D:\\gvim\\vimfiles\\myplug\\ECY_new\\python/server/Main_server.py", line 241, in Pass2Hanlder
    raise

RuntimeError: No active exception to reraise

Traceback (most recent call last):
  File "C:\Users\qwe\AppData\Local\Programs\Python\Python37-32\lib\threading.py", line 885, in _bootstrap
    self._bootstrap_inner()
    ©¦    ©¸ <function Thread._bootstrap_inner at 0x03128108>
    ©¸ <Thread(Thread-2, started daemon 31648)>
  File "C:\Users\qwe\AppData\Local\Programs\Python\Python37-32\lib\threading.py", line 917, in _bootstrap_inner
    self.run()
    ©¦    ©¸ <function Thread.run at 0x03124FA8>
    ©¸ <Thread(Thread-2, started daemon 31648)>
  File "C:\Users\qwe\AppData\Local\Programs\Python\Python37-32\lib\threading.py", line 865, in run
    self._target(*self._args, **self._kwargs)
    ©¦    ©¦        ©¦    ©¦        ©¦    ©¸ {}
    ©¦    ©¦        ©¦    ©¦        ©¸ <Thread(Thread-2, started daemon 31648)>
    ©¦    ©¦        ©¦    ©¸ ()
    ©¦    ©¦        ©¸ <Thread(Thread-2, started daemon 31648)>
    ©¦    ©¸ <bound method GetTodo.Handler of <__main__.GetTodo object at 0x02FAA5D0>>
    ©¸ <Thread(Thread-2, started daemon 31648)>

> File "D:\\gvim\\vimfiles\\myplug\\ECY_new\\python/server/Main_server.py", line 180, in Handler
    todo_dict = self.event_handler.Pass2Hanlder(todo_dict)
    ©¦           ©¦    ©¦             ©¦            ©¸ {'Msg': {'AllTextList': '[installed_completor]\nserver_lib.sources.label.Label = label\nserver_lib.sources.python.python = py...
    ©¦           ©¦    ©¦             ©¸ <function EventHandler.Pass2Hanlder at 0x0324A4B0>
    ©¦           ©¦    ©¸ <__main__.EventHandler object at 0x0329B730>
    ©¦           ©¸ <__main__.GetTodo object at 0x02FAA5D0>
    ©¸ {'Msg': {'AllTextList': '[installed_completor]\nserver_lib.sources.label.Label = label\nserver_lib.sources.python.python = py...

  File "D:\\gvim\\vimfiles\\myplug\\ECY_new\\python/server/Main_server.py", line 241, in Pass2Hanlder
    raise

RuntimeError: No active exception to reraise
Main_server.py 185 Handler DEBUG => exception:
Traceback (most recent call last):
  File "C:\Users\qwe\AppData\Local\Programs\Python\Python37-32\lib\threading.py", line 885, in _bootstrap
    self._bootstrap_inner()
    ©¦    ©¸ <function Thread._bootstrap_inner at 0x03128108>
    ©¸ <Thread(Thread-2, started daemon 31648)>
  File "C:\Users\qwe\AppData\Local\Programs\Python\Python37-32\lib\threading.py", line 917, in _bootstrap_inner
    self.run()
    ©¦    ©¸ <function Thread.run at 0x03124FA8>
    ©¸ <Thread(Thread-2, started daemon 31648)>
  File "C:\Users\qwe\AppData\Local\Programs\Python\Python37-32\lib\threading.py", line 865, in run
    self._target(*self._args, **self._kwargs)
    ©¦    ©¦        ©¦    ©¦        ©¦    ©¸ {}
    ©¦    ©¦        ©¦    ©¦        ©¸ <Thread(Thread-2, started daemon 31648)>
    ©¦    ©¦        ©¦    ©¸ ()
    ©¦    ©¦        ©¸ <Thread(Thread-2, started daemon 31648)>
    ©¦    ©¸ <bound method GetTodo.Handler of <__main__.GetTodo object at 0x02FAA5D0>>
    ©¸ <Thread(Thread-2, started daemon 31648)>

> File "D:\\gvim\\vimfiles\\myplug\\ECY_new\\python/server/Main_server.py", line 180, in Handler
    todo_dict = self.event_handler.Pass2Hanlder(todo_dict)
    ©¦           ©¦    ©¦             ©¦            ©¸ {'Msg': {'AllTextList': '" Press ? for help\n\n.. (up a dir)\n/gvim/vimfiles/myplug/ECY_new/\n+ \x07autoload/\n+ \x07doc/\n+ ...
    ©¦           ©¦    ©¦             ©¸ <function EventHandler.Pass2Hanlder at 0x0324A4B0>
    ©¦           ©¦    ©¸ <__main__.EventHandler object at 0x0329B730>
    ©¦           ©¸ <__main__.GetTodo object at 0x02FAA5D0>
    ©¸ {'Msg': {'AllTextList': '" Press ? for help\n\n.. (up a dir)\n/gvim/vimfiles/myplug/ECY_new/\n+ \x07autoload/\n+ \x07doc/\n+ ...

  File "D:\\gvim\\vimfiles\\myplug\\ECY_new\\python/server/Main_server.py", line 241, in Pass2Hanlder
    raise

RuntimeError: No active exception to reraise

Traceback (most recent call last):
  File "C:\Users\qwe\AppData\Local\Programs\Python\Python37-32\lib\threading.py", line 885, in _bootstrap
    self._bootstrap_inner()
    ©¦    ©¸ <function Thread._bootstrap_inner at 0x03128108>
    ©¸ <Thread(Thread-2, started daemon 31648)>
  File "C:\Users\qwe\AppData\Local\Programs\Python\Python37-32\lib\threading.py", line 917, in _bootstrap_inner
    self.run()
    ©¦    ©¸ <function Thread.run at 0x03124FA8>
    ©¸ <Thread(Thread-2, started daemon 31648)>
  File "C:\Users\qwe\AppData\Local\Programs\Python\Python37-32\lib\threading.py", line 865, in run
    self._target(*self._args, **self._kwargs)
    ©¦    ©¦        ©¦    ©¦        ©¦    ©¸ {}
    ©¦    ©¦        ©¦    ©¦        ©¸ <Thread(Thread-2, started daemon 31648)>
    ©¦    ©¦        ©¦    ©¸ ()
    ©¦    ©¦        ©¸ <Thread(Thread-2, started daemon 31648)>
    ©¦    ©¸ <bound method GetTodo.Handler of <__main__.GetTodo object at 0x02FAA5D0>>
    ©¸ <Thread(Thread-2, started daemon 31648)>

> File "D:\\gvim\\vimfiles\\myplug\\ECY_new\\python/server/Main_server.py", line 180, in Handler
    todo_dict = self.event_handler.Pass2Hanlder(todo_dict)
    ©¦           ©¦    ©¦             ©¦            ©¸ {'Msg': {'AllTextList': '" Press ? for help\n\n.. (up a dir)\n/gvim/vimfiles/myplug/ECY_new/\n+ \x07autoload/\n+ \x07doc/\n+ ...
    ©¦           ©¦    ©¦             ©¸ <function EventHandler.Pass2Hanlder at 0x0324A4B0>
    ©¦           ©¦    ©¸ <__main__.EventHandler object at 0x0329B730>
    ©¦           ©¸ <__main__.GetTodo object at 0x02FAA5D0>
    ©¸ {'Msg': {'AllTextList': '" Press ? for help\n\n.. (up a dir)\n/gvim/vimfiles/myplug/ECY_new/\n+ \x07autoload/\n+ \x07doc/\n+ ...

  File "D:\\gvim\\vimfiles\\myplug\\ECY_new\\python/server/Main_server.py", line 241, in Pass2Hanlder
    raise

RuntimeError: No active exception to reraise
Main_server.py 185 Handler DEBUG => exception:
Traceback (most recent call last):
  File "C:\Users\qwe\AppData\Local\Programs\Python\Python37-32\lib\threading.py", line 885, in _bootstrap
    self._bootstrap_inner()
    ©¦    ©¸ <function Thread._bootstrap_inner at 0x03128108>
    ©¸ <Thread(Thread-2, started daemon 31648)>
  File "C:\Users\qwe\AppData\Local\Programs\Python\Python37-32\lib\threading.py", line 917, in _bootstrap_inner
    self.run()
    ©¦    ©¸ <function Thread.run at 0x03124FA8>
    ©¸ <Thread(Thread-2, started daemon 31648)>
  File "C:\Users\qwe\AppData\Local\Programs\Python\Python37-32\lib\threading.py", line 865, in run
    self._target(*self._args, **self._kwargs)
    ©¦    ©¦        ©¦    ©¦        ©¦    ©¸ {}
    ©¦    ©¦        ©¦    ©¦        ©¸ <Thread(Thread-2, started daemon 31648)>
    ©¦    ©¦        ©¦    ©¸ ()
    ©¦    ©¦        ©¸ <Thread(Thread-2, started daemon 31648)>
    ©¦    ©¸ <bound method GetTodo.Handler of <__main__.GetTodo object at 0x02FAA5D0>>
    ©¸ <Thread(Thread-2, started daemon 31648)>

> File "D:\\gvim\\vimfiles\\myplug\\ECY_new\\python/server/Main_server.py", line 180, in Handler
    todo_dict = self.event_handler.Pass2Hanlder(todo_dict)
    ©¦           ©¦    ©¦             ©¦            ©¸ {'Msg': {'AllTextList': '[installed_completor]\nserver_lib.sources.label.Label = label\nserver_lib.sources.python.python = py...
    ©¦           ©¦    ©¦             ©¸ <function EventHandler.Pass2Hanlder at 0x0324A4B0>
    ©¦           ©¦    ©¸ <__main__.EventHandler object at 0x0329B730>
    ©¦           ©¸ <__main__.GetTodo object at 0x02FAA5D0>
    ©¸ {'Msg': {'AllTextList': '[installed_completor]\nserver_lib.sources.label.Label = label\nserver_lib.sources.python.python = py...

  File "D:\\gvim\\vimfiles\\myplug\\ECY_new\\python/server/Main_server.py", line 241, in Pass2Hanlder
    raise

RuntimeError: No active exception to reraise

Traceback (most recent call last):
  File "C:\Users\qwe\AppData\Local\Programs\Python\Python37-32\lib\threading.py", line 885, in _bootstrap
    self._bootstrap_inner()
    ©¦    ©¸ <function Thread._bootstrap_inner at 0x03128108>
    ©¸ <Thread(Thread-2, started daemon 31648)>
  File "C:\Users\qwe\AppData\Local\Programs\Python\Python37-32\lib\threading.py", line 917, in _bootstrap_inner
    self.run()
    ©¦    ©¸ <function Thread.run at 0x03124FA8>
    ©¸ <Thread(Thread-2, started daemon 31648)>
  File "C:\Users\qwe\AppData\Local\Programs\Python\Python37-32\lib\threading.py", line 865, in run
    self._target(*self._args, **self._kwargs)
    ©¦    ©¦        ©¦    ©¦        ©¦    ©¸ {}
    ©¦    ©¦        ©¦    ©¦        ©¸ <Thread(Thread-2, started daemon 31648)>
    ©¦    ©¦        ©¦    ©¸ ()
    ©¦    ©¦        ©¸ <Thread(Thread-2, started daemon 31648)>
    ©¦    ©¸ <bound method GetTodo.Handler of <__main__.GetTodo object at 0x02FAA5D0>>
    ©¸ <Thread(Thread-2, started daemon 31648)>

> File "D:\\gvim\\vimfiles\\myplug\\ECY_new\\python/server/Main_server.py", line 180, in Handler
    todo_dict = self.event_handler.Pass2Hanlder(todo_dict)
    ©¦           ©¦    ©¦             ©¦            ©¸ {'Msg': {'AllTextList': '[installed_completor]\nserver_lib.sources.label.Label = label\nserver_lib.sources.python.python = py...
    ©¦           ©¦    ©¦             ©¸ <function EventHandler.Pass2Hanlder at 0x0324A4B0>
    ©¦           ©¦    ©¸ <__main__.EventHandler object at 0x0329B730>
    ©¦           ©¸ <__main__.GetTodo object at 0x02FAA5D0>
    ©¸ {'Msg': {'AllTextList': '[installed_completor]\nserver_lib.sources.label.Label = label\nserver_lib.sources.python.python = py...

  File "D:\\gvim\\vimfiles\\myplug\\ECY_new\\python/server/Main_server.py", line 241, in Pass2Hanlder
    raise

RuntimeError: No active exception to reraise
Main_server.py 185 Handler DEBUG => exception:
Traceback (most recent call last):
  File "C:\Users\qwe\AppData\Local\Programs\Python\Python37-32\lib\threading.py", line 885, in _bootstrap
    self._bootstrap_inner()
    ©¦    ©¸ <function Thread._bootstrap_inner at 0x03128108>
    ©¸ <Thread(Thread-2, started daemon 31648)>
  File "C:\Users\qwe\AppData\Local\Programs\Python\Python37-32\lib\threading.py", line 917, in _bootstrap_inner
    self.run()
    ©¦    ©¸ <function Thread.run at 0x03124FA8>
    ©¸ <Thread(Thread-2, started daemon 31648)>
  File "C:\Users\qwe\AppData\Local\Programs\Python\Python37-32\lib\threading.py", line 865, in run
    self._target(*self._args, **self._kwargs)
    ©¦    ©¦        ©¦    ©¦        ©¦    ©¸ {}
    ©¦    ©¦        ©¦    ©¦        ©¸ <Thread(Thread-2, started daemon 31648)>
    ©¦    ©¦        ©¦    ©¸ ()
    ©¦    ©¦        ©¸ <Thread(Thread-2, started daemon 31648)>
    ©¦    ©¸ <bound method GetTodo.Handler of <__main__.GetTodo object at 0x02FAA5D0>>
    ©¸ <Thread(Thread-2, started daemon 31648)>

> File "D:\\gvim\\vimfiles\\myplug\\ECY_new\\python/server/Main_server.py", line 180, in Handler
    todo_dict = self.event_handler.Pass2Hanlder(todo_dict)
    ©¦           ©¦    ©¦             ©¦            ©¸ {'Msg': {'TriggerLength': '1', 'ReturnMatchPoint': True, 'AllTextList': '[installed_completor]\nserver_lib.sources.label.Labe...
    ©¦           ©¦    ©¦             ©¸ <function EventHandler.Pass2Hanlder at 0x0324A4B0>
    ©¦           ©¦    ©¸ <__main__.EventHandler object at 0x0329B730>
    ©¦           ©¸ <__main__.GetTodo object at 0x02FAA5D0>
    ©¸ {'Msg': {'TriggerLength': '1', 'ReturnMatchPoint': True, 'AllTextList': '[installed_completor]\nserver_lib.sources.label.Labe...

  File "D:\\gvim\\vimfiles\\myplug\\ECY_new\\python/server/Main_server.py", line 241, in Pass2Hanlder
    raise

RuntimeError: No active exception to reraise

Traceback (most recent call last):
  File "C:\Users\qwe\AppData\Local\Programs\Python\Python37-32\lib\threading.py", line 885, in _bootstrap
    self._bootstrap_inner()
    ©¦    ©¸ <function Thread._bootstrap_inner at 0x03128108>
    ©¸ <Thread(Thread-2, started daemon 31648)>
  File "C:\Users\qwe\AppData\Local\Programs\Python\Python37-32\lib\threading.py", line 917, in _bootstrap_inner
    self.run()
    ©¦    ©¸ <function Thread.run at 0x03124FA8>
    ©¸ <Thread(Thread-2, started daemon 31648)>
  File "C:\Users\qwe\AppData\Local\Programs\Python\Python37-32\lib\threading.py", line 865, in run
    self._target(*self._args, **self._kwargs)
    ©¦    ©¦        ©¦    ©¦        ©¦    ©¸ {}
    ©¦    ©¦        ©¦    ©¦        ©¸ <Thread(Thread-2, started daemon 31648)>
    ©¦    ©¦        ©¦    ©¸ ()
    ©¦    ©¦        ©¸ <Thread(Thread-2, started daemon 31648)>
    ©¦    ©¸ <bound method GetTodo.Handler of <__main__.GetTodo object at 0x02FAA5D0>>
    ©¸ <Thread(Thread-2, started daemon 31648)>

> File "D:\\gvim\\vimfiles\\myplug\\ECY_new\\python/server/Main_server.py", line 180, in Handler
    todo_dict = self.event_handler.Pass2Hanlder(todo_dict)
    ©¦           ©¦    ©¦             ©¦            ©¸ {'Msg': {'TriggerLength': '1', 'ReturnMatchPoint': True, 'AllTextList': '[installed_completor]\nserver_lib.sources.label.Labe...
    ©¦           ©¦    ©¦             ©¸ <function EventHandler.Pass2Hanlder at 0x0324A4B0>
    ©¦           ©¦    ©¸ <__main__.EventHandler object at 0x0329B730>
    ©¦           ©¸ <__main__.GetTodo object at 0x02FAA5D0>
    ©¸ {'Msg': {'TriggerLength': '1', 'ReturnMatchPoint': True, 'AllTextList': '[installed_completor]\nserver_lib.sources.label.Labe...

  File "D:\\gvim\\vimfiles\\myplug\\ECY_new\\python/server/Main_server.py", line 241, in Pass2Hanlder
    raise

RuntimeError: No active exception to reraise
Main_server.py 185 Handler DEBUG => exception:
Traceback (most recent call last):
  File "C:\Users\qwe\AppData\Local\Programs\Python\Python37-32\lib\threading.py", line 885, in _bootstrap
    self._bootstrap_inner()
    ©¦    ©¸ <function Thread._bootstrap_inner at 0x03128108>
    ©¸ <Thread(Thread-2, started daemon 31648)>
  File "C:\Users\qwe\AppData\Local\Programs\Python\Python37-32\lib\threading.py", line 917, in _bootstrap_inner
    self.run()
    ©¦    ©¸ <function Thread.run at 0x03124FA8>
    ©¸ <Thread(Thread-2, started daemon 31648)>
  File "C:\Users\qwe\AppData\Local\Programs\Python\Python37-32\lib\threading.py", line 865, in run
    self._target(*self._args, **self._kwargs)
    ©¦    ©¦        ©¦    ©¦        ©¦    ©¸ {}
    ©¦    ©¦        ©¦    ©¦        ©¸ <Thread(Thread-2, started daemon 31648)>
    ©¦    ©¦        ©¦    ©¸ ()
    ©¦    ©¦        ©¸ <Thread(Thread-2, started daemon 31648)>
    ©¦    ©¸ <bound method GetTodo.Handler of <__main__.GetTodo object at 0x02FAA5D0>>
    ©¸ <Thread(Thread-2, started daemon 31648)>

> File "D:\\gvim\\vimfiles\\myplug\\ECY_new\\python/server/Main_server.py", line 180, in Handler
    todo_dict = self.event_handler.Pass2Hanlder(todo_dict)
    ©¦           ©¦    ©¦             ©¦            ©¸ {'Msg': {'TriggerLength': '1', 'ReturnMatchPoint': True, 'AllTextList': '[installed_completor]\n.sources.label.Label = label\...
    ©¦           ©¦    ©¦             ©¸ <function EventHandler.Pass2Hanlder at 0x0324A4B0>
    ©¦           ©¦    ©¸ <__main__.EventHandler object at 0x0329B730>
    ©¦           ©¸ <__main__.GetTodo object at 0x02FAA5D0>
    ©¸ {'Msg': {'TriggerLength': '1', 'ReturnMatchPoint': True, 'AllTextList': '[installed_completor]\n.sources.label.Label = label\...

  File "D:\\gvim\\vimfiles\\myplug\\ECY_new\\python/server/Main_server.py", line 241, in Pass2Hanlder
    raise

RuntimeError: No active exception to reraise

Traceback (most recent call last):
  File "C:\Users\qwe\AppData\Local\Programs\Python\Python37-32\lib\threading.py", line 885, in _bootstrap
    self._bootstrap_inner()
    ©¦    ©¸ <function Thread._bootstrap_inner at 0x03128108>
    ©¸ <Thread(Thread-2, started daemon 31648)>
  File "C:\Users\qwe\AppData\Local\Programs\Python\Python37-32\lib\threading.py", line 917, in _bootstrap_inner
    self.run()
    ©¦    ©¸ <function Thread.run at 0x03124FA8>
    ©¸ <Thread(Thread-2, started daemon 31648)>
  File "C:\Users\qwe\AppData\Local\Programs\Python\Python37-32\lib\threading.py", line 865, in run
    self._target(*self._args, **self._kwargs)
    ©¦    ©¦        ©¦    ©¦        ©¦    ©¸ {}
    ©¦    ©¦        ©¦    ©¦        ©¸ <Thread(Thread-2, started daemon 31648)>
    ©¦    ©¦        ©¦    ©¸ ()
    ©¦    ©¦        ©¸ <Thread(Thread-2, started daemon 31648)>
    ©¦    ©¸ <bound method GetTodo.Handler of <__main__.GetTodo object at 0x02FAA5D0>>
    ©¸ <Thread(Thread-2, started daemon 31648)>

> File "D:\\gvim\\vimfiles\\myplug\\ECY_new\\python/server/Main_server.py", line 180, in Handler
    todo_dict = self.event_handler.Pass2Hanlder(todo_dict)
    ©¦           ©¦    ©¦             ©¦            ©¸ {'Msg': {'TriggerLength': '1', 'ReturnMatchPoint': True, 'AllTextList': '[installed_completor]\n.sources.label.Label = label\...
    ©¦           ©¦    ©¦             ©¸ <function EventHandler.Pass2Hanlder at 0x0324A4B0>
    ©¦           ©¦    ©¸ <__main__.EventHandler object at 0x0329B730>
    ©¦           ©¸ <__main__.GetTodo object at 0x02FAA5D0>
    ©¸ {'Msg': {'TriggerLength': '1', 'ReturnMatchPoint': True, 'AllTextList': '[installed_completor]\n.sources.label.Label = label\...

  File "D:\\gvim\\vimfiles\\myplug\\ECY_new\\python/server/Main_server.py", line 241, in Pass2Hanlder
    raise

RuntimeError: No active exception to reraise
Main_server.py 185 Handler DEBUG => exception:
Traceback (most recent call last):
  File "C:\Users\qwe\AppData\Local\Programs\Python\Python37-32\lib\threading.py", line 885, in _bootstrap
    self._bootstrap_inner()
    ©¦    ©¸ <function Thread._bootstrap_inner at 0x03128108>
    ©¸ <Thread(Thread-2, started daemon 31648)>
  File "C:\Users\qwe\AppData\Local\Programs\Python\Python37-32\lib\threading.py", line 917, in _bootstrap_inner
    self.run()
    ©¦    ©¸ <function Thread.run at 0x03124FA8>
    ©¸ <Thread(Thread-2, started daemon 31648)>
  File "C:\Users\qwe\AppData\Local\Programs\Python\Python37-32\lib\threading.py", line 865, in run
    self._target(*self._args, **self._kwargs)
    ©¦    ©¦        ©¦    ©¦        ©¦    ©¸ {}
    ©¦    ©¦        ©¦    ©¦        ©¸ <Thread(Thread-2, started daemon 31648)>
    ©¦    ©¦        ©¦    ©¸ ()
    ©¦    ©¦        ©¸ <Thread(Thread-2, started daemon 31648)>
    ©¦    ©¸ <bound method GetTodo.Handler of <__main__.GetTodo object at 0x02FAA5D0>>
    ©¸ <Thread(Thread-2, started daemon 31648)>

> File "D:\\gvim\\vimfiles\\myplug\\ECY_new\\python/server/Main_server.py", line 180, in Handler
    todo_dict = self.event_handler.Pass2Hanlder(todo_dict)
    ©¦           ©¦    ©¦             ©¦            ©¸ {'Msg': {'TriggerLength': '1', 'ReturnMatchPoint': True, 'AllTextList': '[installed_completor]\n.sources.label.Label = label\...
    ©¦           ©¦    ©¦             ©¸ <function EventHandler.Pass2Hanlder at 0x0324A4B0>
    ©¦           ©¦    ©¸ <__main__.EventHandler object at 0x0329B730>
    ©¦           ©¸ <__main__.GetTodo object at 0x02FAA5D0>
    ©¸ {'Msg': {'TriggerLength': '1', 'ReturnMatchPoint': True, 'AllTextList': '[installed_completor]\n.sources.label.Label = label\...

  File "D:\\gvim\\vimfiles\\myplug\\ECY_new\\python/server/Main_server.py", line 241, in Pass2Hanlder
    raise

RuntimeError: No active exception to reraise

Traceback (most recent call last):
  File "C:\Users\qwe\AppData\Local\Programs\Python\Python37-32\lib\threading.py", line 885, in _bootstrap
    self._bootstrap_inner()
    ©¦    ©¸ <function Thread._bootstrap_inner at 0x03128108>
    ©¸ <Thread(Thread-2, started daemon 31648)>
  File "C:\Users\qwe\AppData\Local\Programs\Python\Python37-32\lib\threading.py", line 917, in _bootstrap_inner
    self.run()
    ©¦    ©¸ <function Thread.run at 0x03124FA8>
    ©¸ <Thread(Thread-2, started daemon 31648)>
  File "C:\Users\qwe\AppData\Local\Programs\Python\Python37-32\lib\threading.py", line 865, in run
    self._target(*self._args, **self._kwargs)
    ©¦    ©¦        ©¦    ©¦        ©¦    ©¸ {}
    ©¦    ©¦        ©¦    ©¦        ©¸ <Thread(Thread-2, started daemon 31648)>
    ©¦    ©¦        ©¦    ©¸ ()
    ©¦    ©¦        ©¸ <Thread(Thread-2, started daemon 31648)>
    ©¦    ©¸ <bound method GetTodo.Handler of <__main__.GetTodo object at 0x02FAA5D0>>
    ©¸ <Thread(Thread-2, started daemon 31648)>

> File "D:\\gvim\\vimfiles\\myplug\\ECY_new\\python/server/Main_server.py", line 180, in Handler
    todo_dict = self.event_handler.Pass2Hanlder(todo_dict)
    ©¦           ©¦    ©¦             ©¦            ©¸ {'Msg': {'TriggerLength': '1', 'ReturnMatchPoint': True, 'AllTextList': '[installed_completor]\n.sources.label.Label = label\...
    ©¦           ©¦    ©¦             ©¸ <function EventHandler.Pass2Hanlder at 0x0324A4B0>
    ©¦           ©¦    ©¸ <__main__.EventHandler object at 0x0329B730>
    ©¦           ©¸ <__main__.GetTodo object at 0x02FAA5D0>
    ©¸ {'Msg': {'TriggerLength': '1', 'ReturnMatchPoint': True, 'AllTextList': '[installed_completor]\n.sources.label.Label = label\...

  File "D:\\gvim\\vimfiles\\myplug\\ECY_new\\python/server/Main_server.py", line 241, in Pass2Hanlder
    raise

RuntimeError: No active exception to reraise
Main_server.py 185 Handler DEBUG => exception:
Traceback (most recent call last):
  File "C:\Users\qwe\AppData\Local\Programs\Python\Python37-32\lib\threading.py", line 885, in _bootstrap
    self._bootstrap_inner()
    ©¦    ©¸ <function Thread._bootstrap_inner at 0x03128108>
    ©¸ <Thread(Thread-2, started daemon 31648)>
  File "C:\Users\qwe\AppData\Local\Programs\Python\Python37-32\lib\threading.py", line 917, in _bootstrap_inner
    self.run()
    ©¦    ©¸ <function Thread.run at 0x03124FA8>
    ©¸ <Thread(Thread-2, started daemon 31648)>
  File "C:\Users\qwe\AppData\Local\Programs\Python\Python37-32\lib\threading.py", line 865, in run
    self._target(*self._args, **self._kwargs)
    ©¦    ©¦        ©¦    ©¦        ©¦    ©¸ {}
    ©¦    ©¦        ©¦    ©¦        ©¸ <Thread(Thread-2, started daemon 31648)>
    ©¦    ©¦        ©¦    ©¸ ()
    ©¦    ©¦        ©¸ <Thread(Thread-2, started daemon 31648)>
    ©¦    ©¸ <bound method GetTodo.Handler of <__main__.GetTodo object at 0x02FAA5D0>>
    ©¸ <Thread(Thread-2, started daemon 31648)>

> File "D:\\gvim\\vimfiles\\myplug\\ECY_new\\python/server/Main_server.py", line 180, in Handler
    todo_dict = self.event_handler.Pass2Hanlder(todo_dict)
    ©¦           ©¦    ©¦             ©¦            ©¸ {'Msg': {'TriggerLength': '1', 'ReturnMatchPoint': True, 'AllTextList': '[installed_completor]\nserver_lib.sources.label.Labe...
    ©¦           ©¦    ©¦             ©¸ <function EventHandler.Pass2Hanlder at 0x0324A4B0>
    ©¦           ©¦    ©¸ <__main__.EventHandler object at 0x0329B730>
    ©¦           ©¸ <__main__.GetTodo object at 0x02FAA5D0>
    ©¸ {'Msg': {'TriggerLength': '1', 'ReturnMatchPoint': True, 'AllTextList': '[installed_completor]\nserver_lib.sources.label.Labe...

  File "D:\\gvim\\vimfiles\\myplug\\ECY_new\\python/server/Main_server.py", line 241, in Pass2Hanlder
    raise

RuntimeError: No active exception to reraise

Traceback (most recent call last):
  File "C:\Users\qwe\AppData\Local\Programs\Python\Python37-32\lib\threading.py", line 885, in _bootstrap
    self._bootstrap_inner()
    ©¦    ©¸ <function Thread._bootstrap_inner at 0x03128108>
    ©¸ <Thread(Thread-2, started daemon 31648)>
  File "C:\Users\qwe\AppData\Local\Programs\Python\Python37-32\lib\threading.py", line 917, in _bootstrap_inner
    self.run()
    ©¦    ©¸ <function Thread.run at 0x03124FA8>
    ©¸ <Thread(Thread-2, started daemon 31648)>
  File "C:\Users\qwe\AppData\Local\Programs\Python\Python37-32\lib\threading.py", line 865, in run
    self._target(*self._args, **self._kwargs)
    ©¦    ©¦        ©¦    ©¦        ©¦    ©¸ {}
    ©¦    ©¦        ©¦    ©¦        ©¸ <Thread(Thread-2, started daemon 31648)>
    ©¦    ©¦        ©¦    ©¸ ()
    ©¦    ©¦        ©¸ <Thread(Thread-2, started daemon 31648)>
    ©¦    ©¸ <bound method GetTodo.Handler of <__main__.GetTodo object at 0x02FAA5D0>>
    ©¸ <Thread(Thread-2, started daemon 31648)>

> File "D:\\gvim\\vimfiles\\myplug\\ECY_new\\python/server/Main_server.py", line 180, in Handler
    todo_dict = self.event_handler.Pass2Hanlder(todo_dict)
    ©¦           ©¦    ©¦             ©¦            ©¸ {'Msg': {'TriggerLength': '1', 'ReturnMatchPoint': True, 'AllTextList': '[installed_completor]\nserver_lib.sources.label.Labe...
    ©¦           ©¦    ©¦             ©¸ <function EventHandler.Pass2Hanlder at 0x0324A4B0>
    ©¦           ©¦    ©¸ <__main__.EventHandler object at 0x0329B730>
    ©¦           ©¸ <__main__.GetTodo object at 0x02FAA5D0>
    ©¸ {'Msg': {'TriggerLength': '1', 'ReturnMatchPoint': True, 'AllTextList': '[installed_completor]\nserver_lib.sources.label.Labe...

  File "D:\\gvim\\vimfiles\\myplug\\ECY_new\\python/server/Main_server.py", line 241, in Pass2Hanlder
    raise

RuntimeError: No active exception to reraise
Main_server.py 185 Handler DEBUG => exception:
Traceback (most recent call last):
  File "C:\Users\qwe\AppData\Local\Programs\Python\Python37-32\lib\threading.py", line 885, in _bootstrap
    self._bootstrap_inner()
    ©¦    ©¸ <function Thread._bootstrap_inner at 0x03128108>
    ©¸ <Thread(Thread-2, started daemon 31648)>
  File "C:\Users\qwe\AppData\Local\Programs\Python\Python37-32\lib\threading.py", line 917, in _bootstrap_inner
    self.run()
    ©¦    ©¸ <function Thread.run at 0x03124FA8>
    ©¸ <Thread(Thread-2, started daemon 31648)>
  File "C:\Users\qwe\AppData\Local\Programs\Python\Python37-32\lib\threading.py", line 865, in run
    self._target(*self._args, **self._kwargs)
    ©¦    ©¦        ©¦    ©¦        ©¦    ©¸ {}
    ©¦    ©¦        ©¦    ©¦        ©¸ <Thread(Thread-2, started daemon 31648)>
    ©¦    ©¦        ©¦    ©¸ ()
    ©¦    ©¦        ©¸ <Thread(Thread-2, started daemon 31648)>
    ©¦    ©¸ <bound method GetTodo.Handler of <__main__.GetTodo object at 0x02FAA5D0>>
    ©¸ <Thread(Thread-2, started daemon 31648)>

> File "D:\\gvim\\vimfiles\\myplug\\ECY_new\\python/server/Main_server.py", line 180, in Handler
    todo_dict = self.event_handler.Pass2Hanlder(todo_dict)
    ©¦           ©¦    ©¦             ©¦            ©¸ {'Msg': {'TriggerLength': '1', 'ReturnMatchPoint': True, 'AllTextList': '[installed_completor]\n.sources.label.Label = label\...
    ©¦           ©¦    ©¦             ©¸ <function EventHandler.Pass2Hanlder at 0x0324A4B0>
    ©¦           ©¦    ©¸ <__main__.EventHandler object at 0x0329B730>
    ©¦           ©¸ <__main__.GetTodo object at 0x02FAA5D0>
    ©¸ {'Msg': {'TriggerLength': '1', 'ReturnMatchPoint': True, 'AllTextList': '[installed_completor]\n.sources.label.Label = label\...

  File "D:\\gvim\\vimfiles\\myplug\\ECY_new\\python/server/Main_server.py", line 241, in Pass2Hanlder
    raise

RuntimeError: No active exception to reraise

Traceback (most recent call last):
  File "C:\Users\qwe\AppData\Local\Programs\Python\Python37-32\lib\threading.py", line 885, in _bootstrap
    self._bootstrap_inner()
    ©¦    ©¸ <function Thread._bootstrap_inner at 0x03128108>
    ©¸ <Thread(Thread-2, started daemon 31648)>
  File "C:\Users\qwe\AppData\Local\Programs\Python\Python37-32\lib\threading.py", line 917, in _bootstrap_inner
    self.run()
    ©¦    ©¸ <function Thread.run at 0x03124FA8>
    ©¸ <Thread(Thread-2, started daemon 31648)>
  File "C:\Users\qwe\AppData\Local\Programs\Python\Python37-32\lib\threading.py", line 865, in run
    self._target(*self._args, **self._kwargs)
    ©¦    ©¦        ©¦    ©¦        ©¦    ©¸ {}
    ©¦    ©¦        ©¦    ©¦        ©¸ <Thread(Thread-2, started daemon 31648)>
    ©¦    ©¦        ©¦    ©¸ ()
    ©¦    ©¦        ©¸ <Thread(Thread-2, started daemon 31648)>
    ©¦    ©¸ <bound method GetTodo.Handler of <__main__.GetTodo object at 0x02FAA5D0>>
    ©¸ <Thread(Thread-2, started daemon 31648)>

> File "D:\\gvim\\vimfiles\\myplug\\ECY_new\\python/server/Main_server.py", line 180, in Handler
    todo_dict = self.event_handler.Pass2Hanlder(todo_dict)
    ©¦           ©¦    ©¦             ©¦            ©¸ {'Msg': {'TriggerLength': '1', 'ReturnMatchPoint': True, 'AllTextList': '[installed_completor]\n.sources.label.Label = label\...
    ©¦           ©¦    ©¦             ©¸ <function EventHandler.Pass2Hanlder at 0x0324A4B0>
    ©¦           ©¦    ©¸ <__main__.EventHandler object at 0x0329B730>
    ©¦           ©¸ <__main__.GetTodo object at 0x02FAA5D0>
    ©¸ {'Msg': {'TriggerLength': '1', 'ReturnMatchPoint': True, 'AllTextList': '[installed_completor]\n.sources.label.Label = label\...

  File "D:\\gvim\\vimfiles\\myplug\\ECY_new\\python/server/Main_server.py", line 241, in Pass2Hanlder
    raise

RuntimeError: No active exception to reraise
Main_server.py 185 Handler DEBUG => exception:
Traceback (most recent call last):
  File "C:\Users\qwe\AppData\Local\Programs\Python\Python37-32\lib\threading.py", line 885, in _bootstrap
    self._bootstrap_inner()
    ©¦    ©¸ <function Thread._bootstrap_inner at 0x03128108>
    ©¸ <Thread(Thread-2, started daemon 31648)>
  File "C:\Users\qwe\AppData\Local\Programs\Python\Python37-32\lib\threading.py", line 917, in _bootstrap_inner
    self.run()
    ©¦    ©¸ <function Thread.run at 0x03124FA8>
    ©¸ <Thread(Thread-2, started daemon 31648)>
  File "C:\Users\qwe\AppData\Local\Programs\Python\Python37-32\lib\threading.py", line 865, in run
    self._target(*self._args, **self._kwargs)
    ©¦    ©¦        ©¦    ©¦        ©¦    ©¸ {}
    ©¦    ©¦        ©¦    ©¦        ©¸ <Thread(Thread-2, started daemon 31648)>
    ©¦    ©¦        ©¦    ©¸ ()
    ©¦    ©¦        ©¸ <Thread(Thread-2, started daemon 31648)>
    ©¦    ©¸ <bound method GetTodo.Handler of <__main__.GetTodo object at 0x02FAA5D0>>
    ©¸ <Thread(Thread-2, started daemon 31648)>

> File "D:\\gvim\\vimfiles\\myplug\\ECY_new\\python/server/Main_server.py", line 180, in Handler
    todo_dict = self.event_handler.Pass2Hanlder(todo_dict)
    ©¦           ©¦    ©¦             ©¦            ©¸ {'Msg': {'TriggerLength': '1', 'ReturnMatchPoint': True, 'AllTextList': '[installed_completor]\n.sources.label.Label = label\...
    ©¦           ©¦    ©¦             ©¸ <function EventHandler.Pass2Hanlder at 0x0324A4B0>
    ©¦           ©¦    ©¸ <__main__.EventHandler object at 0x0329B730>
    ©¦           ©¸ <__main__.GetTodo object at 0x02FAA5D0>
    ©¸ {'Msg': {'TriggerLength': '1', 'ReturnMatchPoint': True, 'AllTextList': '[installed_completor]\n.sources.label.Label = label\...

  File "D:\\gvim\\vimfiles\\myplug\\ECY_new\\python/server/Main_server.py", line 241, in Pass2Hanlder
    raise

RuntimeError: No active exception to reraise

Traceback (most recent call last):
  File "C:\Users\qwe\AppData\Local\Programs\Python\Python37-32\lib\threading.py", line 885, in _bootstrap
    self._bootstrap_inner()
    ©¦    ©¸ <function Thread._bootstrap_inner at 0x03128108>
    ©¸ <Thread(Thread-2, started daemon 31648)>
  File "C:\Users\qwe\AppData\Local\Programs\Python\Python37-32\lib\threading.py", line 917, in _bootstrap_inner
    self.run()
    ©¦    ©¸ <function Thread.run at 0x03124FA8>
    ©¸ <Thread(Thread-2, started daemon 31648)>
  File "C:\Users\qwe\AppData\Local\Programs\Python\Python37-32\lib\threading.py", line 865, in run
    self._target(*self._args, **self._kwargs)
    ©¦    ©¦        ©¦    ©¦        ©¦    ©¸ {}
    ©¦    ©¦        ©¦    ©¦        ©¸ <Thread(Thread-2, started daemon 31648)>
    ©¦    ©¦        ©¦    ©¸ ()
    ©¦    ©¦        ©¸ <Thread(Thread-2, started daemon 31648)>
    ©¦    ©¸ <bound method GetTodo.Handler of <__main__.GetTodo object at 0x02FAA5D0>>
    ©¸ <Thread(Thread-2, started daemon 31648)>

> File "D:\\gvim\\vimfiles\\myplug\\ECY_new\\python/server/Main_server.py", line 180, in Handler
    todo_dict = self.event_handler.Pass2Hanlder(todo_dict)
    ©¦           ©¦    ©¦             ©¦            ©¸ {'Msg': {'TriggerLength': '1', 'ReturnMatchPoint': True, 'AllTextList': '[installed_completor]\n.sources.label.Label = label\...
    ©¦           ©¦    ©¦             ©¸ <function EventHandler.Pass2Hanlder at 0x0324A4B0>
    ©¦           ©¦    ©¸ <__main__.EventHandler object at 0x0329B730>
    ©¦           ©¸ <__main__.GetTodo object at 0x02FAA5D0>
    ©¸ {'Msg': {'TriggerLength': '1', 'ReturnMatchPoint': True, 'AllTextList': '[installed_completor]\n.sources.label.Label = label\...

  File "D:\\gvim\\vimfiles\\myplug\\ECY_new\\python/server/Main_server.py", line 241, in Pass2Hanlder
    raise

RuntimeError: No active exception to reraise
Main_server.py 185 Handler DEBUG => exception:
Traceback (most recent call last):
  File "C:\Users\qwe\AppData\Local\Programs\Python\Python37-32\lib\threading.py", line 885, in _bootstrap
    self._bootstrap_inner()
    ©¦    ©¸ <function Thread._bootstrap_inner at 0x03128108>
    ©¸ <Thread(Thread-2, started daemon 31648)>
  File "C:\Users\qwe\AppData\Local\Programs\Python\Python37-32\lib\threading.py", line 917, in _bootstrap_inner
    self.run()
    ©¦    ©¸ <function Thread.run at 0x03124FA8>
    ©¸ <Thread(Thread-2, started daemon 31648)>
  File "C:\Users\qwe\AppData\Local\Programs\Python\Python37-32\lib\threading.py", line 865, in run
    self._target(*self._args, **self._kwargs)
    ©¦    ©¦        ©¦    ©¦        ©¦    ©¸ {}
    ©¦    ©¦        ©¦    ©¦        ©¸ <Thread(Thread-2, started daemon 31648)>
    ©¦    ©¦        ©¦    ©¸ ()
    ©¦    ©¦        ©¸ <Thread(Thread-2, started daemon 31648)>
    ©¦    ©¸ <bound method GetTodo.Handler of <__main__.GetTodo object at 0x02FAA5D0>>
    ©¸ <Thread(Thread-2, started daemon 31648)>

> File "D:\\gvim\\vimfiles\\myplug\\ECY_new\\python/server/Main_server.py", line 180, in Handler
    todo_dict = self.event_handler.Pass2Hanlder(todo_dict)
    ©¦           ©¦    ©¦             ©¦            ©¸ {'Msg': {'TriggerLength': '1', 'ReturnMatchPoint': True, 'AllTextList': '[installed_completor]\nl.sources.label.Label = label...
    ©¦           ©¦    ©¦             ©¸ <function EventHandler.Pass2Hanlder at 0x0324A4B0>
    ©¦           ©¦    ©¸ <__main__.EventHandler object at 0x0329B730>
    ©¦           ©¸ <__main__.GetTodo object at 0x02FAA5D0>
    ©¸ {'Msg': {'TriggerLength': '1', 'ReturnMatchPoint': True, 'AllTextList': '[installed_completor]\nl.sources.label.Label = label...

  File "D:\\gvim\\vimfiles\\myplug\\ECY_new\\python/server/Main_server.py", line 241, in Pass2Hanlder
    raise

RuntimeError: No active exception to reraise

Traceback (most recent call last):
  File "C:\Users\qwe\AppData\Local\Programs\Python\Python37-32\lib\threading.py", line 885, in _bootstrap
    self._bootstrap_inner()
    ©¦    ©¸ <function Thread._bootstrap_inner at 0x03128108>
    ©¸ <Thread(Thread-2, started daemon 31648)>
  File "C:\Users\qwe\AppData\Local\Programs\Python\Python37-32\lib\threading.py", line 917, in _bootstrap_inner
    self.run()
    ©¦    ©¸ <function Thread.run at 0x03124FA8>
    ©¸ <Thread(Thread-2, started daemon 31648)>
  File "C:\Users\qwe\AppData\Local\Programs\Python\Python37-32\lib\threading.py", line 865, in run
    self._target(*self._args, **self._kwargs)
    ©¦    ©¦        ©¦    ©¦        ©¦    ©¸ {}
    ©¦    ©¦        ©¦    ©¦        ©¸ <Thread(Thread-2, started daemon 31648)>
    ©¦    ©¦        ©¦    ©¸ ()
    ©¦    ©¦        ©¸ <Thread(Thread-2, started daemon 31648)>
    ©¦    ©¸ <bound method GetTodo.Handler of <__main__.GetTodo object at 0x02FAA5D0>>
    ©¸ <Thread(Thread-2, started daemon 31648)>

> File "D:\\gvim\\vimfiles\\myplug\\ECY_new\\python/server/Main_server.py", line 180, in Handler
    todo_dict = self.event_handler.Pass2Hanlder(todo_dict)
    ©¦           ©¦    ©¦             ©¦            ©¸ {'Msg': {'TriggerLength': '1', 'ReturnMatchPoint': True, 'AllTextList': '[installed_completor]\nl.sources.label.Label = label...
    ©¦           ©¦    ©¦             ©¸ <function EventHandler.Pass2Hanlder at 0x0324A4B0>
    ©¦           ©¦    ©¸ <__main__.EventHandler object at 0x0329B730>
    ©¦           ©¸ <__main__.GetTodo object at 0x02FAA5D0>
    ©¸ {'Msg': {'TriggerLength': '1', 'ReturnMatchPoint': True, 'AllTextList': '[installed_completor]\nl.sources.label.Label = label...

  File "D:\\gvim\\vimfiles\\myplug\\ECY_new\\python/server/Main_server.py", line 241, in Pass2Hanlder
    raise

RuntimeError: No active exception to reraise
Main_server.py 185 Handler DEBUG => exception:
Traceback (most recent call last):
  File "C:\Users\qwe\AppData\Local\Programs\Python\Python37-32\lib\threading.py", line 885, in _bootstrap
    self._bootstrap_inner()
    ©¦    ©¸ <function Thread._bootstrap_inner at 0x03128108>
    ©¸ <Thread(Thread-2, started daemon 31648)>
  File "C:\Users\qwe\AppData\Local\Programs\Python\Python37-32\lib\threading.py", line 917, in _bootstrap_inner
    self.run()
    ©¦    ©¸ <function Thread.run at 0x03124FA8>
    ©¸ <Thread(Thread-2, started daemon 31648)>
  File "C:\Users\qwe\AppData\Local\Programs\Python\Python37-32\lib\threading.py", line 865, in run
    self._target(*self._args, **self._kwargs)
    ©¦    ©¦        ©¦    ©¦        ©¦    ©¸ {}
    ©¦    ©¦        ©¦    ©¦        ©¸ <Thread(Thread-2, started daemon 31648)>
    ©¦    ©¦        ©¦    ©¸ ()
    ©¦    ©¦        ©¸ <Thread(Thread-2, started daemon 31648)>
    ©¦    ©¸ <bound method GetTodo.Handler of <__main__.GetTodo object at 0x02FAA5D0>>
    ©¸ <Thread(Thread-2, started daemon 31648)>

> File "D:\\gvim\\vimfiles\\myplug\\ECY_new\\python/server/Main_server.py", line 180, in Handler
    todo_dict = self.event_handler.Pass2Hanlder(todo_dict)
    ©¦           ©¦    ©¦             ©¦            ©¸ {'Msg': {'TriggerLength': '1', 'ReturnMatchPoint': True, 'AllTextList': '[installed_completor]\nli.sources.label.Label = labe...
    ©¦           ©¦    ©¦             ©¸ <function EventHandler.Pass2Hanlder at 0x0324A4B0>
    ©¦           ©¦    ©¸ <__main__.EventHandler object at 0x0329B730>
    ©¦           ©¸ <__main__.GetTodo object at 0x02FAA5D0>
    ©¸ {'Msg': {'TriggerLength': '1', 'ReturnMatchPoint': True, 'AllTextList': '[installed_completor]\nli.sources.label.Label = labe...

  File "D:\\gvim\\vimfiles\\myplug\\ECY_new\\python/server/Main_server.py", line 241, in Pass2Hanlder
    raise

RuntimeError: No active exception to reraise

Traceback (most recent call last):
  File "C:\Users\qwe\AppData\Local\Programs\Python\Python37-32\lib\threading.py", line 885, in _bootstrap
    self._bootstrap_inner()
    ©¦    ©¸ <function Thread._bootstrap_inner at 0x03128108>
    ©¸ <Thread(Thread-2, started daemon 31648)>
  File "C:\Users\qwe\AppData\Local\Programs\Python\Python37-32\lib\threading.py", line 917, in _bootstrap_inner
    self.run()
    ©¦    ©¸ <function Thread.run at 0x03124FA8>
    ©¸ <Thread(Thread-2, started daemon 31648)>
  File "C:\Users\qwe\AppData\Local\Programs\Python\Python37-32\lib\threading.py", line 865, in run
    self._target(*self._args, **self._kwargs)
    ©¦    ©¦        ©¦    ©¦        ©¦    ©¸ {}
    ©¦    ©¦        ©¦    ©¦        ©¸ <Thread(Thread-2, started daemon 31648)>
    ©¦    ©¦        ©¦    ©¸ ()
    ©¦    ©¦        ©¸ <Thread(Thread-2, started daemon 31648)>
    ©¦    ©¸ <bound method GetTodo.Handler of <__main__.GetTodo object at 0x02FAA5D0>>
    ©¸ <Thread(Thread-2, started daemon 31648)>

> File "D:\\gvim\\vimfiles\\myplug\\ECY_new\\python/server/Main_server.py", line 180, in Handler
    todo_dict = self.event_handler.Pass2Hanlder(todo_dict)
    ©¦           ©¦    ©¦             ©¦            ©¸ {'Msg': {'TriggerLength': '1', 'ReturnMatchPoint': True, 'AllTextList': '[installed_completor]\nli.sources.label.Label = labe...
    ©¦           ©¦    ©¦             ©¸ <function EventHandler.Pass2Hanlder at 0x0324A4B0>
    ©¦           ©¦    ©¸ <__main__.EventHandler object at 0x0329B730>
    ©¦           ©¸ <__main__.GetTodo object at 0x02FAA5D0>
    ©¸ {'Msg': {'TriggerLength': '1', 'ReturnMatchPoint': True, 'AllTextList': '[installed_completor]\nli.sources.label.Label = labe...

  File "D:\\gvim\\vimfiles\\myplug\\ECY_new\\python/server/Main_server.py", line 241, in Pass2Hanlder
    raise

RuntimeError: No active exception to reraise
Main_server.py 185 Handler DEBUG => exception:
Traceback (most recent call last):
  File "C:\Users\qwe\AppData\Local\Programs\Python\Python37-32\lib\threading.py", line 885, in _bootstrap
    self._bootstrap_inner()
    ©¦    ©¸ <function Thread._bootstrap_inner at 0x03128108>
    ©¸ <Thread(Thread-2, started daemon 31648)>
  File "C:\Users\qwe\AppData\Local\Programs\Python\Python37-32\lib\threading.py", line 917, in _bootstrap_inner
    self.run()
    ©¦    ©¸ <function Thread.run at 0x03124FA8>
    ©¸ <Thread(Thread-2, started daemon 31648)>
  File "C:\Users\qwe\AppData\Local\Programs\Python\Python37-32\lib\threading.py", line 865, in run
    self._target(*self._args, **self._kwargs)
    ©¦    ©¦        ©¦    ©¦        ©¦    ©¸ {}
    ©¦    ©¦        ©¦    ©¦        ©¸ <Thread(Thread-2, started daemon 31648)>
    ©¦    ©¦        ©¦    ©¸ ()
    ©¦    ©¦        ©¸ <Thread(Thread-2, started daemon 31648)>
    ©¦    ©¸ <bound method GetTodo.Handler of <__main__.GetTodo object at 0x02FAA5D0>>
    ©¸ <Thread(Thread-2, started daemon 31648)>

> File "D:\\gvim\\vimfiles\\myplug\\ECY_new\\python/server/Main_server.py", line 180, in Handler
    todo_dict = self.event_handler.Pass2Hanlder(todo_dict)
    ©¦           ©¦    ©¦             ©¦            ©¸ {'Msg': {'TriggerLength': '1', 'ReturnMatchPoint': True, 'AllTextList': '[installed_completor]\nlib.sources.label.Label = lab...
    ©¦           ©¦    ©¦             ©¸ <function EventHandler.Pass2Hanlder at 0x0324A4B0>
    ©¦           ©¦    ©¸ <__main__.EventHandler object at 0x0329B730>
    ©¦           ©¸ <__main__.GetTodo object at 0x02FAA5D0>
    ©¸ {'Msg': {'TriggerLength': '1', 'ReturnMatchPoint': True, 'AllTextList': '[installed_completor]\nlib.sources.label.Label = lab...

  File "D:\\gvim\\vimfiles\\myplug\\ECY_new\\python/server/Main_server.py", line 241, in Pass2Hanlder
    raise

RuntimeError: No active exception to reraise

Traceback (most recent call last):
  File "C:\Users\qwe\AppData\Local\Programs\Python\Python37-32\lib\threading.py", line 885, in _bootstrap
    self._bootstrap_inner()
    ©¦    ©¸ <function Thread._bootstrap_inner at 0x03128108>
    ©¸ <Thread(Thread-2, started daemon 31648)>
  File "C:\Users\qwe\AppData\Local\Programs\Python\Python37-32\lib\threading.py", line 917, in _bootstrap_inner
    self.run()
    ©¦    ©¸ <function Thread.run at 0x03124FA8>
    ©¸ <Thread(Thread-2, started daemon 31648)>
  File "C:\Users\qwe\AppData\Local\Programs\Python\Python37-32\lib\threading.py", line 865, in run
    self._target(*self._args, **self._kwargs)
    ©¦    ©¦        ©¦    ©¦        ©¦    ©¸ {}
    ©¦    ©¦        ©¦    ©¦        ©¸ <Thread(Thread-2, started daemon 31648)>
    ©¦    ©¦        ©¦    ©¸ ()
    ©¦    ©¦        ©¸ <Thread(Thread-2, started daemon 31648)>
    ©¦    ©¸ <bound method GetTodo.Handler of <__main__.GetTodo object at 0x02FAA5D0>>
    ©¸ <Thread(Thread-2, started daemon 31648)>

> File "D:\\gvim\\vimfiles\\myplug\\ECY_new\\python/server/Main_server.py", line 180, in Handler
    todo_dict = self.event_handler.Pass2Hanlder(todo_dict)
    ©¦           ©¦    ©¦             ©¦            ©¸ {'Msg': {'TriggerLength': '1', 'ReturnMatchPoint': True, 'AllTextList': '[installed_completor]\nlib.sources.label.Label = lab...
    ©¦           ©¦    ©¦             ©¸ <function EventHandler.Pass2Hanlder at 0x0324A4B0>
    ©¦           ©¦    ©¸ <__main__.EventHandler object at 0x0329B730>
    ©¦           ©¸ <__main__.GetTodo object at 0x02FAA5D0>
    ©¸ {'Msg': {'TriggerLength': '1', 'ReturnMatchPoint': True, 'AllTextList': '[installed_completor]\nlib.sources.label.Label = lab...

  File "D:\\gvim\\vimfiles\\myplug\\ECY_new\\python/server/Main_server.py", line 241, in Pass2Hanlder
    raise

RuntimeError: No active exception to reraise
Main_server.py 185 Handler DEBUG => exception:
Traceback (most recent call last):
  File "C:\Users\qwe\AppData\Local\Programs\Python\Python37-32\lib\threading.py", line 885, in _bootstrap
    self._bootstrap_inner()
    ©¦    ©¸ <function Thread._bootstrap_inner at 0x03128108>
    ©¸ <Thread(Thread-2, started daemon 31648)>
  File "C:\Users\qwe\AppData\Local\Programs\Python\Python37-32\lib\threading.py", line 917, in _bootstrap_inner
    self.run()
    ©¦    ©¸ <function Thread.run at 0x03124FA8>
    ©¸ <Thread(Thread-2, started daemon 31648)>
  File "C:\Users\qwe\AppData\Local\Programs\Python\Python37-32\lib\threading.py", line 865, in run
    self._target(*self._args, **self._kwargs)
    ©¦    ©¦        ©¦    ©¦        ©¦    ©¸ {}
    ©¦    ©¦        ©¦    ©¦        ©¸ <Thread(Thread-2, started daemon 31648)>
    ©¦    ©¦        ©¦    ©¸ ()
    ©¦    ©¦        ©¸ <Thread(Thread-2, started daemon 31648)>
    ©¦    ©¸ <bound method GetTodo.Handler of <__main__.GetTodo object at 0x02FAA5D0>>
    ©¸ <Thread(Thread-2, started daemon 31648)>

> File "D:\\gvim\\vimfiles\\myplug\\ECY_new\\python/server/Main_server.py", line 180, in Handler
    todo_dict = self.event_handler.Pass2Hanlder(todo_dict)
    ©¦           ©¦    ©¦             ©¦            ©¸ {'Msg': {'TriggerLength': '1', 'ReturnMatchPoint': True, 'AllTextList': '[installed_completor]\nlib.sources.label.Label = lab...
    ©¦           ©¦    ©¦             ©¸ <function EventHandler.Pass2Hanlder at 0x0324A4B0>
    ©¦           ©¦    ©¸ <__main__.EventHandler object at 0x0329B730>
    ©¦           ©¸ <__main__.GetTodo object at 0x02FAA5D0>
    ©¸ {'Msg': {'TriggerLength': '1', 'ReturnMatchPoint': True, 'AllTextList': '[installed_completor]\nlib.sources.label.Label = lab...

  File "D:\\gvim\\vimfiles\\myplug\\ECY_new\\python/server/Main_server.py", line 241, in Pass2Hanlder
    raise

RuntimeError: No active exception to reraise

Traceback (most recent call last):
  File "C:\Users\qwe\AppData\Local\Programs\Python\Python37-32\lib\threading.py", line 885, in _bootstrap
    self._bootstrap_inner()
    ©¦    ©¸ <function Thread._bootstrap_inner at 0x03128108>
    ©¸ <Thread(Thread-2, started daemon 31648)>
  File "C:\Users\qwe\AppData\Local\Programs\Python\Python37-32\lib\threading.py", line 917, in _bootstrap_inner
    self.run()
    ©¦    ©¸ <function Thread.run at 0x03124FA8>
    ©¸ <Thread(Thread-2, started daemon 31648)>
  File "C:\Users\qwe\AppData\Local\Programs\Python\Python37-32\lib\threading.py", line 865, in run
    self._target(*self._args, **self._kwargs)
    ©¦    ©¦        ©¦    ©¦        ©¦    ©¸ {}
    ©¦    ©¦        ©¦    ©¦        ©¸ <Thread(Thread-2, started daemon 31648)>
    ©¦    ©¦        ©¦    ©¸ ()
    ©¦    ©¦        ©¸ <Thread(Thread-2, started daemon 31648)>
    ©¦    ©¸ <bound method GetTodo.Handler of <__main__.GetTodo object at 0x02FAA5D0>>
    ©¸ <Thread(Thread-2, started daemon 31648)>

> File "D:\\gvim\\vimfiles\\myplug\\ECY_new\\python/server/Main_server.py", line 180, in Handler
    todo_dict = self.event_handler.Pass2Hanlder(todo_dict)
    ©¦           ©¦    ©¦             ©¦            ©¸ {'Msg': {'TriggerLength': '1', 'ReturnMatchPoint': True, 'AllTextList': '[installed_completor]\nlib.sources.label.Label = lab...
    ©¦           ©¦    ©¦             ©¸ <function EventHandler.Pass2Hanlder at 0x0324A4B0>
    ©¦           ©¦    ©¸ <__main__.EventHandler object at 0x0329B730>
    ©¦           ©¸ <__main__.GetTodo object at 0x02FAA5D0>
    ©¸ {'Msg': {'TriggerLength': '1', 'ReturnMatchPoint': True, 'AllTextList': '[installed_completor]\nlib.sources.label.Label = lab...

  File "D:\\gvim\\vimfiles\\myplug\\ECY_new\\python/server/Main_server.py", line 241, in Pass2Hanlder
    raise

RuntimeError: No active exception to reraise
Main_server.py 185 Handler DEBUG => exception:
Traceback (most recent call last):
  File "C:\Users\qwe\AppData\Local\Programs\Python\Python37-32\lib\threading.py", line 885, in _bootstrap
    self._bootstrap_inner()
    ©¦    ©¸ <function Thread._bootstrap_inner at 0x03128108>
    ©¸ <Thread(Thread-2, started daemon 31648)>
  File "C:\Users\qwe\AppData\Local\Programs\Python\Python37-32\lib\threading.py", line 917, in _bootstrap_inner
    self.run()
    ©¦    ©¸ <function Thread.run at 0x03124FA8>
    ©¸ <Thread(Thread-2, started daemon 31648)>
  File "C:\Users\qwe\AppData\Local\Programs\Python\Python37-32\lib\threading.py", line 865, in run
    self._target(*self._args, **self._kwargs)
    ©¦    ©¦        ©¦    ©¦        ©¦    ©¸ {}
    ©¦    ©¦        ©¦    ©¦        ©¸ <Thread(Thread-2, started daemon 31648)>
    ©¦    ©¦        ©¦    ©¸ ()
    ©¦    ©¦        ©¸ <Thread(Thread-2, started daemon 31648)>
    ©¦    ©¸ <bound method GetTodo.Handler of <__main__.GetTodo object at 0x02FAA5D0>>
    ©¸ <Thread(Thread-2, started daemon 31648)>

> File "D:\\gvim\\vimfiles\\myplug\\ECY_new\\python/server/Main_server.py", line 180, in Handler
    todo_dict = self.event_handler.Pass2Hanlder(todo_dict)
    ©¦           ©¦    ©¦             ©¦            ©¸ {'Msg': {'TriggerLength': '1', 'ReturnMatchPoint': True, 'AllTextList': '[installed_completor]\nlib.sources.label.Label = lab...
    ©¦           ©¦    ©¦             ©¸ <function EventHandler.Pass2Hanlder at 0x0324A4B0>
    ©¦           ©¦    ©¸ <__main__.EventHandler object at 0x0329B730>
    ©¦           ©¸ <__main__.GetTodo object at 0x02FAA5D0>
    ©¸ {'Msg': {'TriggerLength': '1', 'ReturnMatchPoint': True, 'AllTextList': '[installed_completor]\nlib.sources.label.Label = lab...

  File "D:\\gvim\\vimfiles\\myplug\\ECY_new\\python/server/Main_server.py", line 241, in Pass2Hanlder
    raise

RuntimeError: No active exception to reraise

Traceback (most recent call last):
  File "C:\Users\qwe\AppData\Local\Programs\Python\Python37-32\lib\threading.py", line 885, in _bootstrap
    self._bootstrap_inner()
    ©¦    ©¸ <function Thread._bootstrap_inner at 0x03128108>
    ©¸ <Thread(Thread-2, started daemon 31648)>
  File "C:\Users\qwe\AppData\Local\Programs\Python\Python37-32\lib\threading.py", line 917, in _bootstrap_inner
    self.run()
    ©¦    ©¸ <function Thread.run at 0x03124FA8>
    ©¸ <Thread(Thread-2, started daemon 31648)>
  File "C:\Users\qwe\AppData\Local\Programs\Python\Python37-32\lib\threading.py", line 865, in run
    self._target(*self._args, **self._kwargs)
    ©¦    ©¦        ©¦    ©¦        ©¦    ©¸ {}
    ©¦    ©¦        ©¦    ©¦        ©¸ <Thread(Thread-2, started daemon 31648)>
    ©¦    ©¦        ©¦    ©¸ ()
    ©¦    ©¦        ©¸ <Thread(Thread-2, started daemon 31648)>
    ©¦    ©¸ <bound method GetTodo.Handler of <__main__.GetTodo object at 0x02FAA5D0>>
    ©¸ <Thread(Thread-2, started daemon 31648)>

> File "D:\\gvim\\vimfiles\\myplug\\ECY_new\\python/server/Main_server.py", line 180, in Handler
    todo_dict = self.event_handler.Pass2Hanlder(todo_dict)
    ©¦           ©¦    ©¦             ©¦            ©¸ {'Msg': {'TriggerLength': '1', 'ReturnMatchPoint': True, 'AllTextList': '[installed_completor]\nlib.sources.label.Label = lab...
    ©¦           ©¦    ©¦             ©¸ <function EventHandler.Pass2Hanlder at 0x0324A4B0>
    ©¦           ©¦    ©¸ <__main__.EventHandler object at 0x0329B730>
    ©¦           ©¸ <__main__.GetTodo object at 0x02FAA5D0>
    ©¸ {'Msg': {'TriggerLength': '1', 'ReturnMatchPoint': True, 'AllTextList': '[installed_completor]\nlib.sources.label.Label = lab...

  File "D:\\gvim\\vimfiles\\myplug\\ECY_new\\python/server/Main_server.py", line 241, in Pass2Hanlder
    raise

RuntimeError: No active exception to reraise
Main_server.py 185 Handler DEBUG => exception:
Traceback (most recent call last):
  File "C:\Users\qwe\AppData\Local\Programs\Python\Python37-32\lib\threading.py", line 885, in _bootstrap
    self._bootstrap_inner()
    ©¦    ©¸ <function Thread._bootstrap_inner at 0x03128108>
    ©¸ <Thread(Thread-2, started daemon 31648)>
  File "C:\Users\qwe\AppData\Local\Programs\Python\Python37-32\lib\threading.py", line 917, in _bootstrap_inner
    self.run()
    ©¦    ©¸ <function Thread.run at 0x03124FA8>
    ©¸ <Thread(Thread-2, started daemon 31648)>
  File "C:\Users\qwe\AppData\Local\Programs\Python\Python37-32\lib\threading.py", line 865, in run
    self._target(*self._args, **self._kwargs)
    ©¦    ©¦        ©¦    ©¦        ©¦    ©¸ {}
    ©¦    ©¦        ©¦    ©¦        ©¸ <Thread(Thread-2, started daemon 31648)>
    ©¦    ©¦        ©¦    ©¸ ()
    ©¦    ©¦        ©¸ <Thread(Thread-2, started daemon 31648)>
    ©¦    ©¸ <bound method GetTodo.Handler of <__main__.GetTodo object at 0x02FAA5D0>>
    ©¸ <Thread(Thread-2, started daemon 31648)>

> File "D:\\gvim\\vimfiles\\myplug\\ECY_new\\python/server/Main_server.py", line 180, in Handler
    todo_dict = self.event_handler.Pass2Hanlder(todo_dict)
    ©¦           ©¦    ©¦             ©¦            ©¸ {'Msg': {'TriggerLength': '1', 'ReturnMatchPoint': True, 'AllTextList': '[installed_completor]\nlib.sources.label.Label = lab...
    ©¦           ©¦    ©¦             ©¸ <function EventHandler.Pass2Hanlder at 0x0324A4B0>
    ©¦           ©¦    ©¸ <__main__.EventHandler object at 0x0329B730>
    ©¦           ©¸ <__main__.GetTodo object at 0x02FAA5D0>
    ©¸ {'Msg': {'TriggerLength': '1', 'ReturnMatchPoint': True, 'AllTextList': '[installed_completor]\nlib.sources.label.Label = lab...

  File "D:\\gvim\\vimfiles\\myplug\\ECY_new\\python/server/Main_server.py", line 241, in Pass2Hanlder
    raise

RuntimeError: No active exception to reraise

Traceback (most recent call last):
  File "C:\Users\qwe\AppData\Local\Programs\Python\Python37-32\lib\threading.py", line 885, in _bootstrap
    self._bootstrap_inner()
    ©¦    ©¸ <function Thread._bootstrap_inner at 0x03128108>
    ©¸ <Thread(Thread-2, started daemon 31648)>
  File "C:\Users\qwe\AppData\Local\Programs\Python\Python37-32\lib\threading.py", line 917, in _bootstrap_inner
    self.run()
    ©¦    ©¸ <function Thread.run at 0x03124FA8>
    ©¸ <Thread(Thread-2, started daemon 31648)>
  File "C:\Users\qwe\AppData\Local\Programs\Python\Python37-32\lib\threading.py", line 865, in run
    self._target(*self._args, **self._kwargs)
    ©¦    ©¦        ©¦    ©¦        ©¦    ©¸ {}
    ©¦    ©¦        ©¦    ©¦        ©¸ <Thread(Thread-2, started daemon 31648)>
    ©¦    ©¦        ©¦    ©¸ ()
    ©¦    ©¦        ©¸ <Thread(Thread-2, started daemon 31648)>
    ©¦    ©¸ <bound method GetTodo.Handler of <__main__.GetTodo object at 0x02FAA5D0>>
    ©¸ <Thread(Thread-2, started daemon 31648)>

> File "D:\\gvim\\vimfiles\\myplug\\ECY_new\\python/server/Main_server.py", line 180, in Handler
    todo_dict = self.event_handler.Pass2Hanlder(todo_dict)
    ©¦           ©¦    ©¦             ©¦            ©¸ {'Msg': {'TriggerLength': '1', 'ReturnMatchPoint': True, 'AllTextList': '[installed_completor]\nlib.sources.label.Label = lab...
    ©¦           ©¦    ©¦             ©¸ <function EventHandler.Pass2Hanlder at 0x0324A4B0>
    ©¦           ©¦    ©¸ <__main__.EventHandler object at 0x0329B730>
    ©¦           ©¸ <__main__.GetTodo object at 0x02FAA5D0>
    ©¸ {'Msg': {'TriggerLength': '1', 'ReturnMatchPoint': True, 'AllTextList': '[installed_completor]\nlib.sources.label.Label = lab...

  File "D:\\gvim\\vimfiles\\myplug\\ECY_new\\python/server/Main_server.py", line 241, in Pass2Hanlder
    raise

RuntimeError: No active exception to reraise
Main_server.py 185 Handler DEBUG => exception:
Traceback (most recent call last):
  File "C:\Users\qwe\AppData\Local\Programs\Python\Python37-32\lib\threading.py", line 885, in _bootstrap
    self._bootstrap_inner()
    ©¦    ©¸ <function Thread._bootstrap_inner at 0x03128108>
    ©¸ <Thread(Thread-2, started daemon 31648)>
  File "C:\Users\qwe\AppData\Local\Programs\Python\Python37-32\lib\threading.py", line 917, in _bootstrap_inner
    self.run()
    ©¦    ©¸ <function Thread.run at 0x03124FA8>
    ©¸ <Thread(Thread-2, started daemon 31648)>
  File "C:\Users\qwe\AppData\Local\Programs\Python\Python37-32\lib\threading.py", line 865, in run
    self._target(*self._args, **self._kwargs)
    ©¦    ©¦        ©¦    ©¦        ©¦    ©¸ {}
    ©¦    ©¦        ©¦    ©¦        ©¸ <Thread(Thread-2, started daemon 31648)>
    ©¦    ©¦        ©¦    ©¸ ()
    ©¦    ©¦        ©¸ <Thread(Thread-2, started daemon 31648)>
    ©¦    ©¸ <bound method GetTodo.Handler of <__main__.GetTodo object at 0x02FAA5D0>>
    ©¸ <Thread(Thread-2, started daemon 31648)>

> File "D:\\gvim\\vimfiles\\myplug\\ECY_new\\python/server/Main_server.py", line 180, in Handler
    todo_dict = self.event_handler.Pass2Hanlder(todo_dict)
    ©¦           ©¦    ©¦             ©¦            ©¸ {'Msg': {'TriggerLength': '1', 'ReturnMatchPoint': True, 'AllTextList': '[installed_completor]\nlib.sources.label.Label = lab...
    ©¦           ©¦    ©¦             ©¸ <function EventHandler.Pass2Hanlder at 0x0324A4B0>
    ©¦           ©¦    ©¸ <__main__.EventHandler object at 0x0329B730>
    ©¦           ©¸ <__main__.GetTodo object at 0x02FAA5D0>
    ©¸ {'Msg': {'TriggerLength': '1', 'ReturnMatchPoint': True, 'AllTextList': '[installed_completor]\nlib.sources.label.Label = lab...

  File "D:\\gvim\\vimfiles\\myplug\\ECY_new\\python/server/Main_server.py", line 241, in Pass2Hanlder
    raise

RuntimeError: No active exception to reraise

Traceback (most recent call last):
  File "C:\Users\qwe\AppData\Local\Programs\Python\Python37-32\lib\threading.py", line 885, in _bootstrap
    self._bootstrap_inner()
    ©¦    ©¸ <function Thread._bootstrap_inner at 0x03128108>
    ©¸ <Thread(Thread-2, started daemon 31648)>
  File "C:\Users\qwe\AppData\Local\Programs\Python\Python37-32\lib\threading.py", line 917, in _bootstrap_inner
    self.run()
    ©¦    ©¸ <function Thread.run at 0x03124FA8>
    ©¸ <Thread(Thread-2, started daemon 31648)>
  File "C:\Users\qwe\AppData\Local\Programs\Python\Python37-32\lib\threading.py", line 865, in run
    self._target(*self._args, **self._kwargs)
    ©¦    ©¦        ©¦    ©¦        ©¦    ©¸ {}
    ©¦    ©¦        ©¦    ©¦        ©¸ <Thread(Thread-2, started daemon 31648)>
    ©¦    ©¦        ©¦    ©¸ ()
    ©¦    ©¦        ©¸ <Thread(Thread-2, started daemon 31648)>
    ©¦    ©¸ <bound method GetTodo.Handler of <__main__.GetTodo object at 0x02FAA5D0>>
    ©¸ <Thread(Thread-2, started daemon 31648)>

> File "D:\\gvim\\vimfiles\\myplug\\ECY_new\\python/server/Main_server.py", line 180, in Handler
    todo_dict = self.event_handler.Pass2Hanlder(todo_dict)
    ©¦           ©¦    ©¦             ©¦            ©¸ {'Msg': {'TriggerLength': '1', 'ReturnMatchPoint': True, 'AllTextList': '[installed_completor]\nlib.sources.label.Label = lab...
    ©¦           ©¦    ©¦             ©¸ <function EventHandler.Pass2Hanlder at 0x0324A4B0>
    ©¦           ©¦    ©¸ <__main__.EventHandler object at 0x0329B730>
    ©¦           ©¸ <__main__.GetTodo object at 0x02FAA5D0>
    ©¸ {'Msg': {'TriggerLength': '1', 'ReturnMatchPoint': True, 'AllTextList': '[installed_completor]\nlib.sources.label.Label = lab...

  File "D:\\gvim\\vimfiles\\myplug\\ECY_new\\python/server/Main_server.py", line 241, in Pass2Hanlder
    raise

RuntimeError: No active exception to reraise
Main_server.py 185 Handler DEBUG => exception:
Traceback (most recent call last):
  File "C:\Users\qwe\AppData\Local\Programs\Python\Python37-32\lib\threading.py", line 885, in _bootstrap
    self._bootstrap_inner()
    ©¦    ©¸ <function Thread._bootstrap_inner at 0x03128108>
    ©¸ <Thread(Thread-2, started daemon 31648)>
  File "C:\Users\qwe\AppData\Local\Programs\Python\Python37-32\lib\threading.py", line 917, in _bootstrap_inner
    self.run()
    ©¦    ©¸ <function Thread.run at 0x03124FA8>
    ©¸ <Thread(Thread-2, started daemon 31648)>
  File "C:\Users\qwe\AppData\Local\Programs\Python\Python37-32\lib\threading.py", line 865, in run
    self._target(*self._args, **self._kwargs)
    ©¦    ©¦        ©¦    ©¦        ©¦    ©¸ {}
    ©¦    ©¦        ©¦    ©¦        ©¸ <Thread(Thread-2, started daemon 31648)>
    ©¦    ©¦        ©¦    ©¸ ()
    ©¦    ©¦        ©¸ <Thread(Thread-2, started daemon 31648)>
    ©¦    ©¸ <bound method GetTodo.Handler of <__main__.GetTodo object at 0x02FAA5D0>>
    ©¸ <Thread(Thread-2, started daemon 31648)>

> File "D:\\gvim\\vimfiles\\myplug\\ECY_new\\python/server/Main_server.py", line 180, in Handler
    todo_dict = self.event_handler.Pass2Hanlder(todo_dict)
    ©¦           ©¦    ©¦             ©¦            ©¸ {'Msg': {'TriggerLength': '1', 'ReturnMatchPoint': True, 'AllTextList': '[installed_completor]\nlib.sources.label.Label = lab...
    ©¦           ©¦    ©¦             ©¸ <function EventHandler.Pass2Hanlder at 0x0324A4B0>
    ©¦           ©¦    ©¸ <__main__.EventHandler object at 0x0329B730>
    ©¦           ©¸ <__main__.GetTodo object at 0x02FAA5D0>
    ©¸ {'Msg': {'TriggerLength': '1', 'ReturnMatchPoint': True, 'AllTextList': '[installed_completor]\nlib.sources.label.Label = lab...

  File "D:\\gvim\\vimfiles\\myplug\\ECY_new\\python/server/Main_server.py", line 241, in Pass2Hanlder
    raise

RuntimeError: No active exception to reraise

Traceback (most recent call last):
  File "C:\Users\qwe\AppData\Local\Programs\Python\Python37-32\lib\threading.py", line 885, in _bootstrap
    self._bootstrap_inner()
    ©¦    ©¸ <function Thread._bootstrap_inner at 0x03128108>
    ©¸ <Thread(Thread-2, started daemon 31648)>
  File "C:\Users\qwe\AppData\Local\Programs\Python\Python37-32\lib\threading.py", line 917, in _bootstrap_inner
    self.run()
    ©¦    ©¸ <function Thread.run at 0x03124FA8>
    ©¸ <Thread(Thread-2, started daemon 31648)>
  File "C:\Users\qwe\AppData\Local\Programs\Python\Python37-32\lib\threading.py", line 865, in run
    self._target(*self._args, **self._kwargs)
    ©¦    ©¦        ©¦    ©¦        ©¦    ©¸ {}
    ©¦    ©¦        ©¦    ©¦        ©¸ <Thread(Thread-2, started daemon 31648)>
    ©¦    ©¦        ©¦    ©¸ ()
    ©¦    ©¦        ©¸ <Thread(Thread-2, started daemon 31648)>
    ©¦    ©¸ <bound method GetTodo.Handler of <__main__.GetTodo object at 0x02FAA5D0>>
    ©¸ <Thread(Thread-2, started daemon 31648)>

> File "D:\\gvim\\vimfiles\\myplug\\ECY_new\\python/server/Main_server.py", line 180, in Handler
    todo_dict = self.event_handler.Pass2Hanlder(todo_dict)
    ©¦           ©¦    ©¦             ©¦            ©¸ {'Msg': {'TriggerLength': '1', 'ReturnMatchPoint': True, 'AllTextList': '[installed_completor]\nlib.sources.label.Label = lab...
    ©¦           ©¦    ©¦             ©¸ <function EventHandler.Pass2Hanlder at 0x0324A4B0>
    ©¦           ©¦    ©¸ <__main__.EventHandler object at 0x0329B730>
    ©¦           ©¸ <__main__.GetTodo object at 0x02FAA5D0>
    ©¸ {'Msg': {'TriggerLength': '1', 'ReturnMatchPoint': True, 'AllTextList': '[installed_completor]\nlib.sources.label.Label = lab...

  File "D:\\gvim\\vimfiles\\myplug\\ECY_new\\python/server/Main_server.py", line 241, in Pass2Hanlder
    raise

RuntimeError: No active exception to reraise
Main_server.py 185 Handler DEBUG => exception:
Traceback (most recent call last):
  File "C:\Users\qwe\AppData\Local\Programs\Python\Python37-32\lib\threading.py", line 885, in _bootstrap
    self._bootstrap_inner()
    ©¦    ©¸ <function Thread._bootstrap_inner at 0x03128108>
    ©¸ <Thread(Thread-2, started daemon 31648)>
  File "C:\Users\qwe\AppData\Local\Programs\Python\Python37-32\lib\threading.py", line 917, in _bootstrap_inner
    self.run()
    ©¦    ©¸ <function Thread.run at 0x03124FA8>
    ©¸ <Thread(Thread-2, started daemon 31648)>
  File "C:\Users\qwe\AppData\Local\Programs\Python\Python37-32\lib\threading.py", line 865, in run
    self._target(*self._args, **self._kwargs)
    ©¦    ©¦        ©¦    ©¦        ©¦    ©¸ {}
    ©¦    ©¦        ©¦    ©¦        ©¸ <Thread(Thread-2, started daemon 31648)>
    ©¦    ©¦        ©¦    ©¸ ()
    ©¦    ©¦        ©¸ <Thread(Thread-2, started daemon 31648)>
    ©¦    ©¸ <bound method GetTodo.Handler of <__main__.GetTodo object at 0x02FAA5D0>>
    ©¸ <Thread(Thread-2, started daemon 31648)>

> File "D:\\gvim\\vimfiles\\myplug\\ECY_new\\python/server/Main_server.py", line 180, in Handler
    todo_dict = self.event_handler.Pass2Hanlder(todo_dict)
    ©¦           ©¦    ©¦             ©¦            ©¸ {'Msg': {'TriggerLength': '1', 'ReturnMatchPoint': True, 'AllTextList': '[installed_completor]\nlib.sources.label.Label = lab...
    ©¦           ©¦    ©¦             ©¸ <function EventHandler.Pass2Hanlder at 0x0324A4B0>
    ©¦           ©¦    ©¸ <__main__.EventHandler object at 0x0329B730>
    ©¦           ©¸ <__main__.GetTodo object at 0x02FAA5D0>
    ©¸ {'Msg': {'TriggerLength': '1', 'ReturnMatchPoint': True, 'AllTextList': '[installed_completor]\nlib.sources.label.Label = lab...

  File "D:\\gvim\\vimfiles\\myplug\\ECY_new\\python/server/Main_server.py", line 241, in Pass2Hanlder
    raise

RuntimeError: No active exception to reraise

Traceback (most recent call last):
  File "C:\Users\qwe\AppData\Local\Programs\Python\Python37-32\lib\threading.py", line 885, in _bootstrap
    self._bootstrap_inner()
    ©¦    ©¸ <function Thread._bootstrap_inner at 0x03128108>
    ©¸ <Thread(Thread-2, started daemon 31648)>
  File "C:\Users\qwe\AppData\Local\Programs\Python\Python37-32\lib\threading.py", line 917, in _bootstrap_inner
    self.run()
    ©¦    ©¸ <function Thread.run at 0x03124FA8>
    ©¸ <Thread(Thread-2, started daemon 31648)>
  File "C:\Users\qwe\AppData\Local\Programs\Python\Python37-32\lib\threading.py", line 865, in run
    self._target(*self._args, **self._kwargs)
    ©¦    ©¦        ©¦    ©¦        ©¦    ©¸ {}
    ©¦    ©¦        ©¦    ©¦        ©¸ <Thread(Thread-2, started daemon 31648)>
    ©¦    ©¦        ©¦    ©¸ ()
    ©¦    ©¦        ©¸ <Thread(Thread-2, started daemon 31648)>
    ©¦    ©¸ <bound method GetTodo.Handler of <__main__.GetTodo object at 0x02FAA5D0>>
    ©¸ <Thread(Thread-2, started daemon 31648)>

> File "D:\\gvim\\vimfiles\\myplug\\ECY_new\\python/server/Main_server.py", line 180, in Handler
    todo_dict = self.event_handler.Pass2Hanlder(todo_dict)
    ©¦           ©¦    ©¦             ©¦            ©¸ {'Msg': {'TriggerLength': '1', 'ReturnMatchPoint': True, 'AllTextList': '[installed_completor]\nlib.sources.label.Label = lab...
    ©¦           ©¦    ©¦             ©¸ <function EventHandler.Pass2Hanlder at 0x0324A4B0>
    ©¦           ©¦    ©¸ <__main__.EventHandler object at 0x0329B730>
    ©¦           ©¸ <__main__.GetTodo object at 0x02FAA5D0>
    ©¸ {'Msg': {'TriggerLength': '1', 'ReturnMatchPoint': True, 'AllTextList': '[installed_completor]\nlib.sources.label.Label = lab...

  File "D:\\gvim\\vimfiles\\myplug\\ECY_new\\python/server/Main_server.py", line 241, in Pass2Hanlder
    raise

RuntimeError: No active exception to reraise
Main_server.py 185 Handler DEBUG => exception:
Traceback (most recent call last):
  File "C:\Users\qwe\AppData\Local\Programs\Python\Python37-32\lib\threading.py", line 885, in _bootstrap
    self._bootstrap_inner()
    ©¦    ©¸ <function Thread._bootstrap_inner at 0x03128108>
    ©¸ <Thread(Thread-2, started daemon 31648)>
  File "C:\Users\qwe\AppData\Local\Programs\Python\Python37-32\lib\threading.py", line 917, in _bootstrap_inner
    self.run()
    ©¦    ©¸ <function Thread.run at 0x03124FA8>
    ©¸ <Thread(Thread-2, started daemon 31648)>
  File "C:\Users\qwe\AppData\Local\Programs\Python\Python37-32\lib\threading.py", line 865, in run
    self._target(*self._args, **self._kwargs)
    ©¦    ©¦        ©¦    ©¦        ©¦    ©¸ {}
    ©¦    ©¦        ©¦    ©¦        ©¸ <Thread(Thread-2, started daemon 31648)>
    ©¦    ©¦        ©¦    ©¸ ()
    ©¦    ©¦        ©¸ <Thread(Thread-2, started daemon 31648)>
    ©¦    ©¸ <bound method GetTodo.Handler of <__main__.GetTodo object at 0x02FAA5D0>>
    ©¸ <Thread(Thread-2, started daemon 31648)>

> File "D:\\gvim\\vimfiles\\myplug\\ECY_new\\python/server/Main_server.py", line 180, in Handler
    todo_dict = self.event_handler.Pass2Hanlder(todo_dict)
    ©¦           ©¦    ©¦             ©¦            ©¸ {'Msg': {'TriggerLength': '1', 'ReturnMatchPoint': True, 'AllTextList': '[installed_completor]\nlib.sources.label.Label = lab...
    ©¦           ©¦    ©¦             ©¸ <function EventHandler.Pass2Hanlder at 0x0324A4B0>
    ©¦           ©¦    ©¸ <__main__.EventHandler object at 0x0329B730>
    ©¦           ©¸ <__main__.GetTodo object at 0x02FAA5D0>
    ©¸ {'Msg': {'TriggerLength': '1', 'ReturnMatchPoint': True, 'AllTextList': '[installed_completor]\nlib.sources.label.Label = lab...

  File "D:\\gvim\\vimfiles\\myplug\\ECY_new\\python/server/Main_server.py", line 241, in Pass2Hanlder
    raise

RuntimeError: No active exception to reraise

Traceback (most recent call last):
  File "C:\Users\qwe\AppData\Local\Programs\Python\Python37-32\lib\threading.py", line 885, in _bootstrap
    self._bootstrap_inner()
    ©¦    ©¸ <function Thread._bootstrap_inner at 0x03128108>
    ©¸ <Thread(Thread-2, started daemon 31648)>
  File "C:\Users\qwe\AppData\Local\Programs\Python\Python37-32\lib\threading.py", line 917, in _bootstrap_inner
    self.run()
    ©¦    ©¸ <function Thread.run at 0x03124FA8>
    ©¸ <Thread(Thread-2, started daemon 31648)>
  File "C:\Users\qwe\AppData\Local\Programs\Python\Python37-32\lib\threading.py", line 865, in run
    self._target(*self._args, **self._kwargs)
    ©¦    ©¦        ©¦    ©¦        ©¦    ©¸ {}
    ©¦    ©¦        ©¦    ©¦        ©¸ <Thread(Thread-2, started daemon 31648)>
    ©¦    ©¦        ©¦    ©¸ ()
    ©¦    ©¦        ©¸ <Thread(Thread-2, started daemon 31648)>
    ©¦    ©¸ <bound method GetTodo.Handler of <__main__.GetTodo object at 0x02FAA5D0>>
    ©¸ <Thread(Thread-2, started daemon 31648)>

> File "D:\\gvim\\vimfiles\\myplug\\ECY_new\\python/server/Main_server.py", line 180, in Handler
    todo_dict = self.event_handler.Pass2Hanlder(todo_dict)
    ©¦           ©¦    ©¦             ©¦            ©¸ {'Msg': {'TriggerLength': '1', 'ReturnMatchPoint': True, 'AllTextList': '[installed_completor]\nlib.sources.label.Label = lab...
    ©¦           ©¦    ©¦             ©¸ <function EventHandler.Pass2Hanlder at 0x0324A4B0>
    ©¦           ©¦    ©¸ <__main__.EventHandler object at 0x0329B730>
    ©¦           ©¸ <__main__.GetTodo object at 0x02FAA5D0>
    ©¸ {'Msg': {'TriggerLength': '1', 'ReturnMatchPoint': True, 'AllTextList': '[installed_completor]\nlib.sources.label.Label = lab...

  File "D:\\gvim\\vimfiles\\myplug\\ECY_new\\python/server/Main_server.py", line 241, in Pass2Hanlder
    raise

RuntimeError: No active exception to reraise
Main_server.py 185 Handler DEBUG => exception:
Traceback (most recent call last):
  File "C:\Users\qwe\AppData\Local\Programs\Python\Python37-32\lib\threading.py", line 885, in _bootstrap
    self._bootstrap_inner()
    ©¦    ©¸ <function Thread._bootstrap_inner at 0x03128108>
    ©¸ <Thread(Thread-2, started daemon 31648)>
  File "C:\Users\qwe\AppData\Local\Programs\Python\Python37-32\lib\threading.py", line 917, in _bootstrap_inner
    self.run()
    ©¦    ©¸ <function Thread.run at 0x03124FA8>
    ©¸ <Thread(Thread-2, started daemon 31648)>
  File "C:\Users\qwe\AppData\Local\Programs\Python\Python37-32\lib\threading.py", line 865, in run
    self._target(*self._args, **self._kwargs)
    ©¦    ©¦        ©¦    ©¦        ©¦    ©¸ {}
    ©¦    ©¦        ©¦    ©¦        ©¸ <Thread(Thread-2, started daemon 31648)>
    ©¦    ©¦        ©¦    ©¸ ()
    ©¦    ©¦        ©¸ <Thread(Thread-2, started daemon 31648)>
    ©¦    ©¸ <bound method GetTodo.Handler of <__main__.GetTodo object at 0x02FAA5D0>>
    ©¸ <Thread(Thread-2, started daemon 31648)>

> File "D:\\gvim\\vimfiles\\myplug\\ECY_new\\python/server/Main_server.py", line 180, in Handler
    todo_dict = self.event_handler.Pass2Hanlder(todo_dict)
    ©¦           ©¦    ©¦             ©¦            ©¸ {'Msg': {'TriggerLength': '1', 'ReturnMatchPoint': True, 'AllTextList': '[installed_completor]\nlib.sources.label.Label = lab...
    ©¦           ©¦    ©¦             ©¸ <function EventHandler.Pass2Hanlder at 0x0324A4B0>
    ©¦           ©¦    ©¸ <__main__.EventHandler object at 0x0329B730>
    ©¦           ©¸ <__main__.GetTodo object at 0x02FAA5D0>
    ©¸ {'Msg': {'TriggerLength': '1', 'ReturnMatchPoint': True, 'AllTextList': '[installed_completor]\nlib.sources.label.Label = lab...

  File "D:\\gvim\\vimfiles\\myplug\\ECY_new\\python/server/Main_server.py", line 241, in Pass2Hanlder
    raise

RuntimeError: No active exception to reraise

Traceback (most recent call last):
  File "C:\Users\qwe\AppData\Local\Programs\Python\Python37-32\lib\threading.py", line 885, in _bootstrap
    self._bootstrap_inner()
    ©¦    ©¸ <function Thread._bootstrap_inner at 0x03128108>
    ©¸ <Thread(Thread-2, started daemon 31648)>
  File "C:\Users\qwe\AppData\Local\Programs\Python\Python37-32\lib\threading.py", line 917, in _bootstrap_inner
    self.run()
    ©¦    ©¸ <function Thread.run at 0x03124FA8>
    ©¸ <Thread(Thread-2, started daemon 31648)>
  File "C:\Users\qwe\AppData\Local\Programs\Python\Python37-32\lib\threading.py", line 865, in run
    self._target(*self._args, **self._kwargs)
    ©¦    ©¦        ©¦    ©¦        ©¦    ©¸ {}
    ©¦    ©¦        ©¦    ©¦        ©¸ <Thread(Thread-2, started daemon 31648)>
    ©¦    ©¦        ©¦    ©¸ ()
    ©¦    ©¦        ©¸ <Thread(Thread-2, started daemon 31648)>
    ©¦    ©¸ <bound method GetTodo.Handler of <__main__.GetTodo object at 0x02FAA5D0>>
    ©¸ <Thread(Thread-2, started daemon 31648)>

> File "D:\\gvim\\vimfiles\\myplug\\ECY_new\\python/server/Main_server.py", line 180, in Handler
    todo_dict = self.event_handler.Pass2Hanlder(todo_dict)
    ©¦           ©¦    ©¦             ©¦            ©¸ {'Msg': {'TriggerLength': '1', 'ReturnMatchPoint': True, 'AllTextList': '[installed_completor]\nlib.sources.label.Label = lab...
    ©¦           ©¦    ©¦             ©¸ <function EventHandler.Pass2Hanlder at 0x0324A4B0>
    ©¦           ©¦    ©¸ <__main__.EventHandler object at 0x0329B730>
    ©¦           ©¸ <__main__.GetTodo object at 0x02FAA5D0>
    ©¸ {'Msg': {'TriggerLength': '1', 'ReturnMatchPoint': True, 'AllTextList': '[installed_completor]\nlib.sources.label.Label = lab...

  File "D:\\gvim\\vimfiles\\myplug\\ECY_new\\python/server/Main_server.py", line 241, in Pass2Hanlder
    raise

RuntimeError: No active exception to reraise
